Workbook

Sheet ריכוז
A1: חשבון מס' | B1: כתב כמויות תחנת מנחם בגין, חולון - מחירון דקל שיפוצים - מהדורת ינואר 26
A2: 4
A4: סעיף | B4: תאור | C4: יח' | D4: מחיר | E4: הנחת קבלן 15% | F4: תוספת דירה מאוכלסת 5% | G4: סה"כ מחיר יחידה | H4: כמות למטלה | I4: 1 | K4: =I4+1 -> 2 | M4: =K4+1 -> 3 | O4: =M4+1 -> 4 | Q4: =O4+1 -> 5 | S4: 6 | U4: 7 | W4: 8 | Y4: 9 | AA4: 10 | AC4: 11 | AE4: 12 | AG4: 13 | AI4: 14 | AK4: 15 | AM4: ="סה""כ כמות חשבון מס' " & A2 -> סה"כ כמות חשבון מס' 4 | AN4: ="סה""כ סכום חשבון מס' " & A2 -> סה"כ סכום חשבון מס' 4
B5: תאור | C5: יח' | D5: מחיר | E5: הנחת קבלן 15% | F5: תוספת דירה מאוכלסת 5% | G5: סה"כ מחיר יחידה | M5: ='3'!C1 -> מלניק | O5: אורי | Q5: מזל | S5: דורף | U5: זליכה | W5: ארמה | Y5: עבדי | AA5: חודזייב | AC5: בן גרשון | AE5: חליפה | AG5: פרימן | AI5: בן יאיר | AK5: השלמה לחשבון 2
B6: תאור | C6: יח' | D6: מחיר | E6: הנחת קבלן 15% | F6: תוספת דירה מאוכלסת 5% | G6: סה"כ מחיר יחידה | M6: ='3'!D1 -> 1573 | O6: 1778 | Q6: 1525 | S6: 1540 | U6: 1808 | W6: 1811 | Y6: 1700 | AA6: 1812 | AC6: 1695 | AE6: 1674 | AG6: 1708 | AI6: 1691
A7: סעיף | B7: תאור | C7: יח' | D7: מחיר | E7: הנחת קבלן 15% | F7: תוספת דירה מאוכלסת 5% | G7: סה"כ מחיר יחידה | I7: כמות | J7: סה"כ לדירה | K7: כמות | L7: סה"כ לדירה | M7: כמות | N7: סה"כ לדירה | O7: כמות | P7: סה"כ לדירה | Q7: כמות | R7: סה"כ לדירה | S7: כמות | T7: סה"כ לדירה | U7: כמות | V7: סה"כ לדירה | W7: כמות | X7: סה"כ לדירה | Y7: כמות | Z7: סה"כ לדירה | AA7: כמות | AB7: סה"כ לדירה | AC7: כמות | AD7: סה"כ לדירה | AE7: כמות | AF7: סה"כ לדירה | AG7: כמות | AH7: סה"כ לדירה | AI7: כמות | AJ7: סה"כ לדירה | AK7: כמות | AL7: סה"כ לדירה
A8: 09 | B8: עבודות טיח | AP8: =IF(G8="","",_xlfn.XLOOKUP(A8,'[1]סעיפים חסרים'!$A:$A,'[1]סעיפים חסרים'!$B:$B,"אין"))
A9: 09.011 | B9: טיח פנים | AP9: =IF(G9="","",_xlfn.XLOOKUP(A9,'[1]סעיפים חסרים'!$A:$A,'[1]סעיפים חסרים'!$B:$B,"אין"))
A10: 09.011.9030 | B10: תיקוני טיח פנים קיים על שטחים מישוריים ברצועות רוחב מעל 15 ס"מ ועד 30 ס"מ לאחר הנחת קווי מים, חשמל וכד' בקירות, סביב משקופי חלונות ודלתות שהורכבו בקירות קיימים, במפגשים בין קירות ו/או תקרות חדשים לקיימים הכל לרבות סיתות והתאמת עובי הטיח החדש לקיים | C10: מ' | D10: 64 | E10: =IF(D10="","",D10*0.15) -> 9.6 | F10: =IF(D10="","",D10*0.05) -> 3.2 | G10: =IF(D10="","",D10*1.05*0.85) -> 57.12 | J10: =IF(D10="","",I10*G10) -> 0 | L10: =IF(G10="","",K10*G10) -> 0 | M10: =IF(D10="","",_xlfn.XLOOKUP(A10,'3'!A:A,'3'!D:D,IF($M$6=0,0,"ERROR"))) -> 43.4 | N10: =IF(G10="","",M10*G10) -> 2479.008 | O10: =IF(D10="","",_xlfn.XLOOKUP(A10,'4'!A:A,'4'!D:D,IF($O$6=0,0,"ERROR"))) -> 0 | P10: =IF(G10="","",O10*G10) -> 0 | Q10: =IF(D10="","",_xlfn.XLOOKUP(A10,'5'!A:A,'5'!D:D,IF($Q$6=0,0,"ERROR"))) -> 59.47 | R10: =IF(G10="","",Q10*G10) -> 3396.9264 | S10: =IF(D10="","",_xlfn.XLOOKUP(A10,'6'!A:A,'6'!D:D,IF($Q$6=0,0,"ERROR"))) -> 34.25 | T10: =IF(G10="","",S10*G10) -> 1956.36 | U10: =IF(D10="","",_xlfn.XLOOKUP(A10,'7'!A:A,'7'!D:D,IF($U$6=0,0,"ERROR"))) -> 41.24 | V10: =IF(G10="","",U10*G10) -> 2355.6288 | W10: =IF(D10="","",_xlfn.XLOOKUP(A10,'8'!A:A,'8'!D:D,IF($U$6=0,0,"ERROR"))) -> 41.24 | X10: =IF(G10="","",W10*G10) -> 2355.6288 | Y10: =IF(D10="","",_xlfn.XLOOKUP(A10,'9'!A:A,'9'!D:D,IF($U$6=0,0,"ERROR"))) -> 35.55 | Z10: =IF(G10="","",Y10*G10) -> 2030.616 | AA10: =IF(D10="","",_xlfn.XLOOKUP(A10,'10'!A:A,'10'!D:D,IF($U$6=0,0,"ERROR"))) -> 30.08 | AB10: =IF(G10="","",AA10*G10) -> 1718.1696 | AC10: =IF(D10="","",_xlfn.XLOOKUP(A10,'11'!A:A,'11'!D:D,IF($U$6=0,0,"ERROR"))) -> 30.91 | AD10: =IF(G10="","",AC10*G10) -> 1765.5792 | AE10: =IF(D10="","",_xlfn.XLOOKUP(A10,'12'!A:A,'12'!D:D,IF($U$6=0,0,"ERROR"))) -> 11.32 | AF10: =IF(G10="","",AE10*G10) -> 646.5984 | AG10: =IF(D10="","",_xlfn.XLOOKUP(A10,'13'!A:A,'13'!D:D,IF($U$6=0,0,"ERROR"))) -> 31.36 | AH10: =IF(G10="","",AG10*G10) -> 1791.2832 | AI10: =IF(D10="","",_xlfn.XLOOKUP(A10,'14'!A:A,'14'!D:D,IF($U$6=0,0,"ERROR"))) -> 0 | AJ10: =IF(G10="","",AI10*G10) -> 0 | AM10: =IF(D10="","",Q10+O10+M10+K10+I10+S10+U10+W10+Y10+AA10+AC10+AE10+AG10+AI10) -> 358.82 | AN10: =IF(D10="","",R10+P10+N10+L10+J10+T10+V10+X10+Z10+AB10+AD10+AH10+AF10+AJ10) -> 20495.798 | AO10: =IF(AN10="","",IF(AM10*G10=AN10,"הכל טוב","לא טוב")) -> הכל טוב
A11: 11 | B11: עבודות צביעה | E11: =IF(D11="","",D11*0.15) | F11: =IF(D11="","",D11*0.05) | G11: =IF(D11="","",D11*1.05*0.85) | J11: =IF(D11="","",I11*G11) | L11: =IF(G11="","",K11*G11) | M11: =IF(D11="","",_xlfn.XLOOKUP(A11,'3'!A:A,'3'!D:D,IF($M$6=0,0,"ERROR"))) | N11: =IF(G11="","",M11*G11) | O11: =IF(D11="","",_xlfn.XLOOKUP(A11,'4'!A:A,'4'!D:D,IF($O$6=0,0,"ERROR"))) | P11: =IF(G11="","",O11*G11) | Q11: =IF(D11="","",_xlfn.XLOOKUP(A11,'5'!A:A,'5'!D:D,IF($Q$6=0,0,"ERROR"))) | R11: =IF(G11="","",Q11*G11) | S11: =IF(D11="","",_xlfn.XLOOKUP(A11,'6'!A:A,'6'!D:D,IF($Q$6=0,0,"ERROR"))) | T11: =IF(G11="","",S11*G11) | U11: =IF(D11="","",_xlfn.XLOOKUP(A11,'7'!A:A,'7'!D:D,IF($U$6=0,0,"ERROR"))) | V11: =IF(G11="","",U11*G11) | W11: =IF(D11="","",_xlfn.XLOOKUP(A11,'8'!A:A,'8'!D:D,IF($U$6=0,0,"ERROR"))) | X11: =IF(G11="","",W11*G11) | Y11: =IF(D11="","",_xlfn.XLOOKUP(A11,'9'!A:A,'9'!D:D,IF($U$6=0,0,"ERROR"))) | Z11: =IF(G11="","",Y11*G11) | AA11: =IF(D11="","",_xlfn.XLOOKUP(A11,'10'!A:A,'10'!D:D,IF($U$6=0,0,"ERROR"))) | AB11: =IF(G11="","",AA11*G11) | AC11: =IF(D11="","",_xlfn.XLOOKUP(A11,'11'!A:A,'11'!D:D,IF($U$6=0,0,"ERROR"))) | AD11: =IF(G11="","",AC11*G11) | AE11: =IF(D11="","",_xlfn.XLOOKUP(A11,'12'!A:A,'12'!D:D,IF($U$6=0,0,"ERROR"))) | AF11: =IF(G11="","",AE11*G11) | AG11: =IF(D11="","",_xlfn.XLOOKUP(A11,'13'!A:A,'13'!D:D,IF($U$6=0,0,"ERROR"))) | AH11: =IF(G11="","",AG11*G11) | AI11: =IF(D11="","",_xlfn.XLOOKUP(A11,'14'!A:A,'14'!D:D,IF($U$6=0,0,"ERROR"))) | AJ11: =IF(G11="","",AI11*G11) | AM11: =IF(D11="","",Q11+O11+M11+K11+I11+S11+U11+W11+Y11+AA11+AC11+AE11+AG11+AI11) | AN11: =IF(D11="","",R11+P11+N11+L11+J11+T11+V11+X11+Z11+AB11+AD11+AH11+AF11+AJ11) | AO11: =IF(AN11="","",IF(AM11*G11=AN11,"הכל טוב","לא טוב"))
A12: 11.011 | B12: צבע וסיוד פנים, על טיח, בטון, בלוקים וגבס | E12: =IF(D12="","",D12*0.15) | F12: =IF(D12="","",D12*0.05) | G12: =IF(D12="","",D12*1.05*0.85) | J12: =IF(D12="","",I12*G12) | L12: =IF(G12="","",K12*G12) | M12: =IF(D12="","",_xlfn.XLOOKUP(A12,'3'!A:A,'3'!D:D,IF($M$6=0,0,"ERROR"))) | N12: =IF(G12="","",M12*G12) | O12: =IF(D12="","",_xlfn.XLOOKUP(A12,'4'!A:A,'4'!D:D,IF($O$6=0,0,"ERROR"))) | P12: =IF(G12="","",O12*G12) | Q12: =IF(D12="","",_xlfn.XLOOKUP(A12,'5'!A:A,'5'!D:D,IF($Q$6=0,0,"ERROR"))) | R12: =IF(G12="","",Q12*G12) | S12: =IF(D12="","",_xlfn.XLOOKUP(A12,'6'!A:A,'6'!D:D,IF($Q$6=0,0,"ERROR"))) | T12: =IF(G12="","",S12*G12) | U12: =IF(D12="","",_xlfn.XLOOKUP(A12,'7'!A:A,'7'!D:D,IF($U$6=0,0,"ERROR"))) | V12: =IF(G12="","",U12*G12) | W12: =IF(D12="","",_xlfn.XLOOKUP(A12,'8'!A:A,'8'!D:D,IF($U$6=0,0,"ERROR"))) | X12: =IF(G12="","",W12*G12) | Y12: =IF(D12="","",_xlfn.XLOOKUP(A12,'9'!A:A,'9'!D:D,IF($U$6=0,0,"ERROR"))) | Z12: =IF(G12="","",Y12*G12) | AA12: =IF(D12="","",_xlfn.XLOOKUP(A12,'10'!A:A,'10'!D:D,IF($U$6=0,0,"ERROR"))) | AB12: =IF(G12="","",AA12*G12) | AC12: =IF(D12="","",_xlfn.XLOOKUP(A12,'11'!A:A,'11'!D:D,IF($U$6=0,0,"ERROR"))) | AD12: =IF(G12="","",AC12*G12) | AE12: =IF(D12="","",_xlfn.XLOOKUP(A12,'12'!A:A,'12'!D:D,IF($U$6=0,0,"ERROR"))) | AF12: =IF(G12="","",AE12*G12) | AG12: =IF(D12="","",_xlfn.XLOOKUP(A12,'13'!A:A,'13'!D:D,IF($U$6=0,0,"ERROR"))) | AH12: =IF(G12="","",AG12*G12) | AI12: =IF(D12="","",_xlfn.XLOOKUP(A12,'14'!A:A,'14'!D:D,IF($U$6=0,0,"ERROR"))) | AJ12: =IF(G12="","",AI12*G12) | AM12: =IF(D12="","",Q12+O12+M12+K12+I12+S12+U12+W12+Y12+AA12+AC12+AE12+AG12+AI12) | AN12: =IF(D12="","",R12+P12+N12+L12+J12+T12+V12+X12+Z12+AB12+AD12+AH12+AF12+AJ12) | AO12: =IF(AN12="","",IF(AM12*G12=AN12,"הכל טוב","לא טוב"))
A13: 11.011.9660 | B13: חידוש צבע פנים על קירות בדירת חדר מרוהטת בשטח 25-35 מ"ר ובגובה עד 2.70 מ'. הקירות ייצבעו בצבע אקרילי, ללא צביעת התקרות, לרבות הסרת צבע רופף, תיקונים קלים וסתימת חורים, ליטוש הקיר וניקוי שאריות הצבע בגמר העבודה | C13: קומפ | D13: 1770 | E13: =IF(D13="","",D13*0.15) -> 265.5 | F13: =IF(D13="","",D13*0.05) -> 88.5 | G13: =IF(D13="","",D13*1.05*0.85) -> 1579.725 | J13: =IF(D13="","",I13*G13) -> 0 | L13: =IF(G13="","",K13*G13) -> 0 | M13: =IF(D13="","",_xlfn.XLOOKUP(A13,'3'!A:A,'3'!D:D,IF($M$6=0,0,"ERROR"))) -> 5 | N13: =IF(G13="","",M13*G13) -> 7898.625 | O13: =IF(D13="","",_xlfn.XLOOKUP(A13,'4'!A:A,'4'!D:D,IF($O$6=0,0,"ERROR"))) -> 0 | P13: =IF(G13="","",O13*G13) -> 0 | Q13: =IF(D13="","",_xlfn.XLOOKUP(A13,'5'!A:A,'5'!D:D,IF($Q$6=0,0,"ERROR"))) -> 5 | R13: =IF(G13="","",Q13*G13) -> 7898.625 | S13: =IF(D13="","",_xlfn.XLOOKUP(A13,'6'!A:A,'6'!D:D,IF($Q$6=0,0,"ERROR"))) -> 4 | T13: =IF(G13="","",S13*G13) -> 6318.9 | U13: =IF(D13="","",_xlfn.XLOOKUP(A13,'7'!A:A,'7'!D:D,IF($U$6=0,0,"ERROR"))) -> 4 | V13: =IF(G13="","",U13*G13) -> 6318.9 | W13: =IF(D13="","",_xlfn.XLOOKUP(A13,'8'!A:A,'8'!D:D,IF($U$6=0,0,"ERROR"))) -> 4 | X13: =IF(G13="","",W13*G13) -> 6318.9 | Y13: =IF(D13="","",_xlfn.XLOOKUP(A13,'9'!A:A,'9'!D:D,IF($U$6=0,0,"ERROR"))) -> 3 | Z13: =IF(G13="","",Y13*G13) -> 4739.175 | AA13: =IF(D13="","",_xlfn.XLOOKUP(A13,'10'!A:A,'10'!D:D,IF($U$6=0,0,"ERROR"))) -> 4 | AB13: =IF(G13="","",AA13*G13) -> 6318.9 | AC13: =IF(D13="","",_xlfn.XLOOKUP(A13,'11'!A:A,'11'!D:D,IF($U$6=0,0,"ERROR"))) -> 3 | AD13: =IF(G13="","",AC13*G13) -> 4739.175 | AE13: =IF(D13="","",_xlfn.XLOOKUP(A13,'12'!A:A,'12'!D:D,IF($U$6=0,0,"ERROR"))) -> 2 | AF13: =IF(G13="","",AE13*G13) -> 3159.45 | AG13: =IF(D13="","",_xlfn.XLOOKUP(A13,'13'!A:A,'13'!D:D,IF($U$6=0,0,"ERROR"))) -> 3 | AH13: =IF(G13="","",AG13*G13) -> 4739.175 | AI13: =IF(D13="","",_xlfn.XLOOKUP(A13,'14'!A:A,'14'!D:D,IF($U$6=0,0,"ERROR"))) -> 0 | AJ13: =IF(G13="","",AI13*G13) -> 0 | AM13: =IF(D13="","",Q13+O13+M13+K13+I13+S13+U13+W13+Y13+AA13+AC13+AE13+AG13+AI13) -> 37 | AN13: =IF(D13="","",R13+P13+N13+L13+J13+T13+V13+X13+Z13+AB13+AD13+AH13+AF13+AJ13) -> 58449.825 | AO13: =IF(AN13="","",IF(AM13*G13=AN13,"הכל טוב","לא טוב")) -> הכל טוב
A14: 12 | B14: עבודות אלומיניום | E14: =IF(D14="","",D14*0.15) | F14: =IF(D14="","",D14*0.05) | G14: =IF(D14="","",D14*1.05*0.85) | J14: =IF(D14="","",I14*G14) | L14: =IF(G14="","",K14*G14) | M14: =IF(D14="","",_xlfn.XLOOKUP(A14,'3'!A:A,'3'!D:D,IF($M$6=0,0,"ERROR"))) | N14: =IF(G14="","",M14*G14) | O14: =IF(D14="","",_xlfn.XLOOKUP(A14,'4'!A:A,'4'!D:D,IF($O$6=0,0,"ERROR"))) | P14: =IF(G14="","",O14*G14) | Q14: =IF(D14="","",_xlfn.XLOOKUP(A14,'5'!A:A,'5'!D:D,IF($Q$6=0,0,"ERROR"))) | R14: =IF(G14="","",Q14*G14) | S14: =IF(D14="","",_xlfn.XLOOKUP(A14,'6'!A:A,'6'!D:D,IF($Q$6=0,0,"ERROR"))) | T14: =IF(G14="","",S14*G14) | U14: =IF(D14="","",_xlfn.XLOOKUP(A14,'7'!A:A,'7'!D:D,IF($U$6=0,0,"ERROR"))) | V14: =IF(G14="","",U14*G14) | W14: =IF(D14="","",_xlfn.XLOOKUP(A14,'8'!A:A,'8'!D:D,IF($U$6=0,0,"ERROR"))) | X14: =IF(G14="","",W14*G14) | Y14: =IF(D14="","",_xlfn.XLOOKUP(A14,'9'!A:A,'9'!D:D,IF($U$6=0,0,"ERROR"))) | Z14: =IF(G14="","",Y14*G14) | AA14: =IF(D14="","",_xlfn.XLOOKUP(A14,'10'!A:A,'10'!D:D,IF($U$6=0,0,"ERROR"))) | AB14: =IF(G14="","",AA14*G14) | AC14: =IF(D14="","",_xlfn.XLOOKUP(A14,'11'!A:A,'11'!D:D,IF($U$6=0,0,"ERROR"))) | AD14: =IF(G14="","",AC14*G14) | AE14: =IF(D14="","",_xlfn.XLOOKUP(A14,'12'!A:A,'12'!D:D,IF($U$6=0,0,"ERROR"))) | AF14: =IF(G14="","",AE14*G14) | AG14: =IF(D14="","",_xlfn.XLOOKUP(A14,'13'!A:A,'13'!D:D,IF($U$6=0,0,"ERROR"))) | AH14: =IF(G14="","",AG14*G14) | AI14: =IF(D14="","",_xlfn.XLOOKUP(A14,'14'!A:A,'14'!D:D,IF($U$6=0,0,"ERROR"))) | AJ14: =IF(G14="","",AI14*G14) | AM14: =IF(D14="","",Q14+O14+M14+K14+I14+S14+U14+W14+Y14+AA14+AC14+AE14+AG14+AI14) | AN14: =IF(D14="","",R14+P14+N14+L14+J14+T14+V14+X14+Z14+AB14+AD14+AH14+AF14+AJ14) | AO14: =IF(AN14="","",IF(AM14*G14=AN14,"הכל טוב","לא טוב"))
A15: 12.011 | B15: חלון אלומיניום נגרר אגף על אגף (הזזה) של 2 אגפים ב-2 מסלולים | E15: =IF(D15="","",D15*0.15) | F15: =IF(D15="","",D15*0.05) | G15: =IF(D15="","",D15*1.05*0.85) | J15: =IF(D15="","",I15*G15) | L15: =IF(G15="","",K15*G15) | M15: =IF(D15="","",_xlfn.XLOOKUP(A15,'3'!A:A,'3'!D:D,IF($M$6=0,0,"ERROR"))) | N15: =IF(G15="","",M15*G15) | O15: =IF(D15="","",_xlfn.XLOOKUP(A15,'4'!A:A,'4'!D:D,IF($O$6=0,0,"ERROR"))) | P15: =IF(G15="","",O15*G15) | Q15: =IF(D15="","",_xlfn.XLOOKUP(A15,'5'!A:A,'5'!D:D,IF($Q$6=0,0,"ERROR"))) | R15: =IF(G15="","",Q15*G15) | S15: =IF(D15="","",_xlfn.XLOOKUP(A15,'6'!A:A,'6'!D:D,IF($Q$6=0,0,"ERROR"))) | T15: =IF(G15="","",S15*G15) | U15: =IF(D15="","",_xlfn.XLOOKUP(A15,'7'!A:A,'7'!D:D,IF($U$6=0,0,"ERROR"))) | V15: =IF(G15="","",U15*G15) | W15: =IF(D15="","",_xlfn.XLOOKUP(A15,'8'!A:A,'8'!D:D,IF($U$6=0,0,"ERROR"))) | X15: =IF(G15="","",W15*G15) | Y15: =IF(D15="","",_xlfn.XLOOKUP(A15,'9'!A:A,'9'!D:D,IF($U$6=0,0,"ERROR"))) | Z15: =IF(G15="","",Y15*G15) | AA15: =IF(D15="","",_xlfn.XLOOKUP(A15,'10'!A:A,'10'!D:D,IF($U$6=0,0,"ERROR"))) | AB15: =IF(G15="","",AA15*G15) | AC15: =IF(D15="","",_xlfn.XLOOKUP(A15,'11'!A:A,'11'!D:D,IF($U$6=0,0,"ERROR"))) | AD15: =IF(G15="","",AC15*G15) | AE15: =IF(D15="","",_xlfn.XLOOKUP(A15,'12'!A:A,'12'!D:D,IF($U$6=0,0,"ERROR"))) | AF15: =IF(G15="","",AE15*G15) | AG15: =IF(D15="","",_xlfn.XLOOKUP(A15,'13'!A:A,'13'!D:D,IF($U$6=0,0,"ERROR"))) | AH15: =IF(G15="","",AG15*G15) | AI15: =IF(D15="","",_xlfn.XLOOKUP(A15,'14'!A:A,'14'!D:D,IF($U$6=0,0,"ERROR"))) | AJ15: =IF(G15="","",AI15*G15) | AM15: =IF(D15="","",Q15+O15+M15+K15+I15+S15+U15+W15+Y15+AA15+AC15+AE15+AG15+AI15) | AN15: =IF(D15="","",R15+P15+N15+L15+J15+T15+V15+X15+Z15+AB15+AD15+AH15+AF15+AJ15) | AO15: =IF(AN15="","",IF(AM15*G15=AN15,"הכל טוב","לא טוב"))
A16: 12.011.0210 | B16: חלון נגרר אגף על אגף של 2 אגפים ב-2 מסלולים מאולגן/צבוע כדוגמת קליל קלאסי 7000 או ש"ע, זכוכית שקופה בידודית 5+6+6 מ"מ, בשטח מעל 1.0 מ"ר ועד 2.0 מ"ר | C16: מ"ר | D16: 1760 | E16: =IF(D16="","",D16*0.15) -> 264 | F16: =IF(D16="","",D16*0.05) -> 88 | G16: =IF(D16="","",D16*1.05*0.85) -> 1570.8 | J16: =IF(D16="","",I16*G16) -> 0 | L16: =IF(G16="","",K16*G16) -> 0 | M16: =IF(D16="","",_xlfn.XLOOKUP(A16,'3'!A:A,'3'!D:D,IF($M$6=0,0,"ERROR"))) -> 0 | N16: =IF(G16="","",M16*G16) -> 0 | O16: =IF(D16="","",_xlfn.XLOOKUP(A16,'4'!A:A,'4'!D:D,IF($O$6=0,0,"ERROR"))) -> 0 | P16: =IF(G16="","",O16*G16) -> 0 | Q16: =IF(D16="","",_xlfn.XLOOKUP(A16,'5'!A:A,'5'!D:D,IF($Q$6=0,0,"ERROR"))) -> 0 | R16: =IF(G16="","",Q16*G16) -> 0 | S16: =IF(D16="","",_xlfn.XLOOKUP(A16,'6'!A:A,'6'!D:D,IF($Q$6=0,0,"ERROR"))) -> 0 | T16: =IF(G16="","",S16*G16) -> 0 | U16: =IF(D16="","",_xlfn.XLOOKUP(A16,'7'!A:A,'7'!D:D,IF($U$6=0,0,"ERROR"))) -> 0 | V16: =IF(G16="","",U16*G16) -> 0 | W16: =IF(D16="","",_xlfn.XLOOKUP(A16,'8'!A:A,'8'!D:D,IF($U$6=0,0,"ERROR"))) -> 0 | X16: =IF(G16="","",W16*G16) -> 0 | Y16: =IF(D16="","",_xlfn.XLOOKUP(A16,'9'!A:A,'9'!D:D,IF($U$6=0,0,"ERROR"))) -> 0 | Z16: =IF(G16="","",Y16*G16) -> 0 | AA16: =IF(D16="","",_xlfn.XLOOKUP(A16,'10'!A:A,'10'!D:D,IF($U$6=0,0,"ERROR"))) -> 0 | AB16: =IF(G16="","",AA16*G16) -> 0 | AC16: =IF(D16="","",_xlfn.XLOOKUP(A16,'11'!A:A,'11'!D:D,IF($U$6=0,0,"ERROR"))) -> 0 | AD16: =IF(G16="","",AC16*G16) -> 0 | AE16: =IF(D16="","",_xlfn.XLOOKUP(A16,'12'!A:A,'12'!D:D,IF($U$6=0,0,"ERROR"))) -> 0 | AF16: =IF(G16="","",AE16*G16) -> 0 | AG16: =IF(D16="","",_xlfn.XLOOKUP(A16,'13'!A:A,'13'!D:D,IF($U$6=0,0,"ERROR"))) -> 0 | AH16: =IF(G16="","",AG16*G16) -> 0 | AI16: =IF(D16="","",_xlfn.XLOOKUP(A16,'14'!A:A,'14'!D:D,IF($U$6=0,0,"ERROR"))) -> 1.722 | AJ16: =IF(G16="","",AI16*G16) -> 2704.9176 | AM16: =IF(D16="","",Q16+O16+M16+K16+I16+S16+U16+W16+Y16+AA16+AC16+AE16+AG16+AI16) -> 1.722 | AN16: =IF(D16="","",R16+P16+N16+L16+J16+T16+V16+X16+Z16+AB16+AD16+AH16+AF16+AJ16) -> 2704.9176 | AO16: =IF(AN16="","",IF(AM16*G16=AN16,"הכל טוב","לא טוב")) -> הכל טוב
A17: 12.011.0270 | B17: חלון נגרר אגף על אגף של 2 אגפים ב-2 מסלולים מאולגן/צבוע כדוגמת קליל קלאסי 9000 או ש"ע, זכוכית שקופה בידודית מחוסמת דו צדדי 6+10+8 מ"מ, בשטח מעל 2.0 מ"ר ועד 3.0 מ"ר | C17: מ"ר | D17: 1980 | E17: =IF(D17="","",D17*0.15) -> 297 | F17: =IF(D17="","",D17*0.05) -> 99 | G17: =IF(D17="","",D17*1.05*0.85) -> 1767.15 | J17: =IF(D17="","",I17*G17) -> 0 | L17: =IF(G17="","",K17*G17) -> 0 | M17: =IF(D17="","",_xlfn.XLOOKUP(A17,'3'!A:A,'3'!D:D,IF($M$6=0,0,"ERROR"))) -> 12.325 | N17: =IF(G17="","",M17*G17) -> 21780.124 | O17: =IF(D17="","",_xlfn.XLOOKUP(A17,'4'!A:A,'4'!D:D,IF($O$6=0,0,"ERROR"))) -> 2.485 | P17: =IF(G17="","",O17*G17) -> 4391.3677 | Q17: =IF(D17="","",_xlfn.XLOOKUP(A17,'5'!A:A,'5'!D:D,IF($Q$6=0,0,"ERROR"))) -> 18.825 | R17: =IF(G17="","",Q17*G17) -> 33266.599 | S17: =IF(D17="","",_xlfn.XLOOKUP(A17,'6'!A:A,'6'!D:D,IF($Q$6=0,0,"ERROR"))) -> 11.16 | T17: =IF(G17="","",S17*G17) -> 19721.394 | U17: =IF(D17="","",_xlfn.XLOOKUP(A17,'7'!A:A,'7'!D:D,IF($U$6=0,0,"ERROR"))) -> 9.212 | V17: =IF(G17="","",U17*G17) -> 16278.986 | W17: =IF(D17="","",_xlfn.XLOOKUP(A17,'8'!A:A,'8'!D:D,IF($U$6=0,0,"ERROR"))) -> 11.21 | X17: =IF(G17="","",W17*G17) -> 19809.751 | Y17: =IF(D17="","",_xlfn.XLOOKUP(A17,'9'!A:A,'9'!D:D,IF($U$6=0,0,"ERROR"))) -> 10.18 | Z17: =IF(G17="","",Y17*G17) -> 17989.587 | AA17: =IF(D17="","",_xlfn.XLOOKUP(A17,'10'!A:A,'10'!D:D,IF($U$6=0,0,"ERROR"))) -> 9.1668 | AB17: =IF(G17="","",AA17*G17) -> 16199.111 | AC17: =IF(D17="","",_xlfn.XLOOKUP(A17,'11'!A:A,'11'!D:D,IF($U$6=0,0,"ERROR"))) -> 10.05 | AD17: =IF(G17="","",AC17*G17) -> 17759.857 | AE17: =IF(D17="","",_xlfn.XLOOKUP(A17,'12'!A:A,'12'!D:D,IF($U$6=0,0,"ERROR"))) -> 4 | AF17: =IF(G17="","",AE17*G17) -> 7068.6 | AG17: =IF(D17="","",_xlfn.XLOOKUP(A17,'13'!A:A,'13'!D:D,IF($U$6=0,0,"ERROR"))) -> 5.655 | AH17: =IF(G17="","",AG17*G17) -> 9993.2332 | AI17: =IF(D17="","",_xlfn.XLOOKUP(A17,'14'!A:A,'14'!D:D,IF($U$6=0,0,"ERROR"))) -> 9.972 | AJ17: =IF(G17="","",AI17*G17) -> 17622.02 | AM17: =IF(D17="","",Q17+O17+M17+K17+I17+S17+U17+W17+Y17+AA17+AC17+AE17+AG17+AI17) -> 114.2408 | AN17: =IF(D17="","",R17+P17+N17+L17+J17+T17+V17+X17+Z17+AB17+AD17+AH17+AF17+AJ17) -> 201880.63 | AO17: =IF(AN17="","",IF(AM17*G17=AN17,"הכל טוב","לא טוב")) -> הכל טוב
A18: 12.012.0100 | B18: חלון נגרר אגף על אגף של 3 אגפים ב-3 מסלולים מאולגן/צבוע כדוגמת קליל קלאסי 9000 או ש"ע, זכוכית שקופה בידודית 5+6+6 מ"מ, בשטח מעל 1.0 מ"ר ועד 2.0 מ"ר | C18: מ"ר | D18: 2210 | E18: =IF(D18="","",D18*0.15) -> 331.5 | F18: =IF(D18="","",D18*0.05) -> 110.5 | G18: =IF(D18="","",D18*1.05*0.85) -> 1972.425 | J18: =IF(D18="","",I18*G18) -> 0 | L18: =IF(G18="","",K18*G18) -> 0 | M18: =IF(D18="","",_xlfn.XLOOKUP(A18,'3'!A:A,'3'!D:D,IF($M$6=0,0,"ERROR"))) -> 0 | N18: =IF(G18="","",M18*G18) -> 0 | O18: =IF(D18="","",_xlfn.XLOOKUP(A18,'4'!A:A,'4'!D:D,IF($O$6=0,0,"ERROR"))) -> 0 | P18: =IF(G18="","",O18*G18) -> 0 | Q18: =IF(D18="","",_xlfn.XLOOKUP(A18,'5'!A:A,'5'!D:D,IF($Q$6=0,0,"ERROR"))) -> 9.96 | R18: =IF(G18="","",Q18*G18) -> 19645.353 | S18: =IF(D18="","",_xlfn.XLOOKUP(A18,'6'!A:A,'6'!D:D,IF($Q$6=0,0,"ERROR"))) -> 0 | T18: =IF(G18="","",S18*G18) -> 0 | U18: =IF(D18="","",_xlfn.XLOOKUP(A18,'7'!A:A,'7'!D:D,IF($U$6=0,0,"ERROR"))) -> 0 | V18: =IF(G18="","",U18*G18) -> 0 | W18: =IF(D18="","",_xlfn.XLOOKUP(A18,'8'!A:A,'8'!D:D,IF($U$6=0,0,"ERROR"))) -> 0 | X18: =IF(G18="","",W18*G18) -> 0 | Y18: =IF(D18="","",_xlfn.XLOOKUP(A18,'9'!A:A,'9'!D:D,IF($U$6=0,0,"ERROR"))) -> 0 | Z18: =IF(G18="","",Y18*G18) -> 0 | AA18: =IF(D18="","",_xlfn.XLOOKUP(A18,'10'!A:A,'10'!D:D,IF($U$6=0,0,"ERROR"))) -> 0 | AB18: =IF(G18="","",AA18*G18) -> 0 | AC18: =IF(D18="","",_xlfn.XLOOKUP(A18,'11'!A:A,'11'!D:D,IF($U$6=0,0,"ERROR"))) -> 0 | AD18: =IF(G18="","",AC18*G18) -> 0 | AE18: =IF(D18="","",_xlfn.XLOOKUP(A18,'12'!A:A,'12'!D:D,IF($U$6=0,0,"ERROR"))) -> 0 | AF18: =IF(G18="","",AE18*G18) -> 0 | AG18: =IF(D18="","",_xlfn.XLOOKUP(A18,'13'!A:A,'13'!D:D,IF($U$6=0,0,"ERROR"))) -> 0 | AH18: =IF(G18="","",AG18*G18) -> 0 | AI18: =IF(D18="","",_xlfn.XLOOKUP(A18,'14'!A:A,'14'!D:D,IF($U$6=0,0,"ERROR"))) -> 0 | AJ18: =IF(G18="","",AI18*G18) -> 0 | AM18: =IF(D18="","",Q18+O18+M18+K18+I18+S18+U18+W18+Y18+AA18+AC18+AE18+AG18+AI18) -> 9.96 | AN18: =IF(D18="","",R18+P18+N18+L18+J18+T18+V18+X18+Z18+AB18+AD18+AH18+AF18+AJ18) -> 19645.353 | AO18: =IF(AN18="","",IF(AM18*G18=AN18,"הכל טוב","לא טוב")) -> הכל טוב
A19: 12.011.1001 | B19: תוספת עבור חלק קבוע בחלון נגרר אגף על אגף של 2 אגפים. התוספת הינה 15% למחיר מ"ר של החלון | C19: קומפ | D19: 0.15 | E19: =IF(D19="","",D19*0.15) -> 0.0225 | F19: =IF(D19="","",D19*0.05) -> 0.0075 | G19: =IF(D19="","",D19*1.05*0.85) -> 0.133875 | J19: =IF(D19="","",I19*G19) -> 0 | L19: =IF(G19="","",K19*G19) -> 0 | M19: =IF(D19="","",_xlfn.XLOOKUP(A19,'3'!A:A,'3'!D:D,IF($M$6=0,0,"ERROR"))) -> 0 | N19: =IF(G19="","",M19*G19) -> 0 | O19: =IF(D19="","",_xlfn.XLOOKUP(A19,'4'!A:A,'4'!D:D,IF($O$6=0,0,"ERROR"))) -> 4920.3 | P19: =IF(G19="","",O19*G19) -> 658.70516 | Q19: =IF(D19="","",_xlfn.XLOOKUP(A19,'5'!A:A,'5'!D:D,IF($Q$6=0,0,"ERROR"))) -> 59285.1 | R19: =IF(G19="","",Q19*G19) -> 7936.7928 | S19: =IF(D19="","",_xlfn.XLOOKUP(A19,'6'!A:A,'6'!D:D,IF($Q$6=0,0,"ERROR"))) -> 22096.8 | T19: =IF(G19="","",S19*G19) -> 2958.2091 | U19: =IF(D19="","",_xlfn.XLOOKUP(A19,'7'!A:A,'7'!D:D,IF($U$6=0,0,"ERROR"))) -> 0 | V19: =IF(G19="","",U19*G19) -> 0 | W19: =IF(D19="","",_xlfn.XLOOKUP(A19,'8'!A:A,'8'!D:D,IF($U$6=0,0,"ERROR"))) -> 0 | X19: =IF(G19="","",W19*G19) -> 0 | Y19: =IF(D19="","",_xlfn.XLOOKUP(A19,'9'!A:A,'9'!D:D,IF($U$6=0,0,"ERROR"))) -> 6557.76 | Z19: =IF(G19="","",Y19*G19) -> 877.92012 | AA19: =IF(D19="","",_xlfn.XLOOKUP(A19,'10'!A:A,'10'!D:D,IF($U$6=0,0,"ERROR"))) -> 0 | AB19: =IF(G19="","",AA19*G19) -> 0 | AC19: =IF(D19="","",_xlfn.XLOOKUP(A19,'11'!A:A,'11'!D:D,IF($U$6=0,0,"ERROR"))) -> 12553.2 | AD19: =IF(G19="","",AC19*G19) -> 1680.5596 | AE19: =IF(D19="","",_xlfn.XLOOKUP(A19,'12'!A:A,'12'!D:D,IF($U$6=0,0,"ERROR"))) -> 7068 | AF19: =IF(G19="","",AE19*G19) -> 946.2285 | AG19: =IF(D19="","",_xlfn.XLOOKUP(A19,'13'!A:A,'13'!D:D,IF($U$6=0,0,"ERROR"))) -> 7312.68 | AH19: =IF(G19="","",AG19*G19) -> 978.98504 | AI19: =IF(D19="","",_xlfn.XLOOKUP(A19,'14'!A:A,'14'!D:D,IF($U$6=0,0,"ERROR"))) -> 6415.2 | AJ19: =IF(G19="","",AI19*G19) -> 858.8349 | AM19: =IF(D19="","",Q19+O19+M19+K19+I19+S19+U19+W19+Y19+AA19+AC19+AE19+AG19+AI19) -> 126209.04 | AN19: =IF(D19="","",R19+P19+N19+L19+J19+T19+V19+X19+Z19+AB19+AD19+AH19+AF19+AJ19) -> 16896.235 | AO19: =IF(AN19="","",IF(AM19*G19=AN19,"הכל טוב","לא טוב")) -> הכל טוב
A20: 12.011.9000 | B20: פירוק חלונות אלומיניום ומשקופיהם בשטח של עד 2 מ"ר | C20: יח' | D20: 140 | E20: =IF(D20="","",D20*0.15) -> 21 | F20: =IF(D20="","",D20*0.05) -> 7 | G20: =IF(D20="","",D20*1.05*0.85) -> 124.95 | J20: =IF(D20="","",I20*G20) -> 0 | L20: =IF(G20="","",K20*G20) -> 0 | M20: =IF(D20="","",_xlfn.XLOOKUP(A20,'3'!A:A,'3'!D:D,IF($M$6=0,0,"ERROR"))) -> 0 | N20: =IF(G20="","",M20*G20) -> 0 | O20: =IF(D20="","",_xlfn.XLOOKUP(A20,'4'!A:A,'4'!D:D,IF($O$6=0,0,"ERROR"))) -> 0 | P20: =IF(G20="","",O20*G20) -> 0 | Q20: =IF(D20="","",_xlfn.XLOOKUP(A20,'5'!A:A,'5'!D:D,IF($Q$6=0,0,"ERROR"))) -> 0 | R20: =IF(G20="","",Q20*G20) -> 0 | S20: =IF(D20="","",_xlfn.XLOOKUP(A20,'6'!A:A,'6'!D:D,IF($Q$6=0,0,"ERROR"))) -> 0 | T20: =IF(G20="","",S20*G20) -> 0 | U20: =IF(D20="","",_xlfn.XLOOKUP(A20,'7'!A:A,'7'!D:D,IF($U$6=0,0,"ERROR"))) -> 3 | V20: =IF(G20="","",U20*G20) -> 374.85 | W20: =IF(D20="","",_xlfn.XLOOKUP(A20,'8'!A:A,'8'!D:D,IF($U$6=0,0,"ERROR"))) -> 0 | X20: =IF(G20="","",W20*G20) -> 0 | Y20: =IF(D20="","",_xlfn.XLOOKUP(A20,'9'!A:A,'9'!D:D,IF($U$6=0,0,"ERROR"))) -> 1 | Z20: =IF(G20="","",Y20*G20) -> 124.95 | AA20: =IF(D20="","",_xlfn.XLOOKUP(A20,'10'!A:A,'10'!D:D,IF($U$6=0,0,"ERROR"))) -> 2 | AB20: =IF(G20="","",AA20*G20) -> 249.9 | AC20: =IF(D20="","",_xlfn.XLOOKUP(A20,'11'!A:A,'11'!D:D,IF($U$6=0,0,"ERROR"))) -> 0 | AD20: =IF(G20="","",AC20*G20) -> 0 | AE20: =IF(D20="","",_xlfn.XLOOKUP(A20,'12'!A:A,'12'!D:D,IF($U$6=0,0,"ERROR"))) -> 2 | AF20: =IF(G20="","",AE20*G20) -> 249.9 | AG20: =IF(D20="","",_xlfn.XLOOKUP(A20,'13'!A:A,'13'!D:D,IF($U$6=0,0,"ERROR"))) -> 3 | AH20: =IF(G20="","",AG20*G20) -> 374.85 | AI20: =IF(D20="","",_xlfn.XLOOKUP(A20,'14'!A:A,'14'!D:D,IF($U$6=0,0,"ERROR"))) -> 0 | AJ20: =IF(G20="","",AI20*G20) -> 0 | AM20: =IF(D20="","",Q20+O20+M20+K20+I20+S20+U20+W20+Y20+AA20+AC20+AE20+AG20+AI20) -> 11 | AN20: =IF(D20="","",R20+P20+N20+L20+J20+T20+V20+X20+Z20+AB20+AD20+AH20+AF20+AJ20) -> 1374.45 | AO20: =IF(AN20="","",IF(AM20*G20=AN20,"הכל טוב","לא טוב")) -> הכל טוב
A21: 12.011.9016 | B21: פירוק חלונות אלומיניום ומשקופיהם בשטח של מעל 2 מ"ר ועד 3 מ"ר | C21: יח' | D21: 240 | E21: =IF(D21="","",D21*0.15) -> 36 | F21: =IF(D21="","",D21*0.05) -> 12 | G21: =IF(D21="","",D21*1.05*0.85) -> 214.2 | J21: =IF(D21="","",I21*G21) -> 0 | L21: =IF(G21="","",K21*G21) -> 0 | M21: =IF(D21="","",_xlfn.XLOOKUP(A21,'3'!A:A,'3'!D:D,IF($M$6=0,0,"ERROR"))) -> 5 | N21: =IF(G21="","",M21*G21) -> 1071 | O21: =IF(D21="","",_xlfn.XLOOKUP(A21,'4'!A:A,'4'!D:D,IF($O$6=0,0,"ERROR"))) -> 1 | P21: =IF(G21="","",O21*G21) -> 214.2 | Q21: =IF(D21="","",_xlfn.XLOOKUP(A21,'5'!A:A,'5'!D:D,IF($Q$6=0,0,"ERROR"))) -> 0 | R21: =IF(G21="","",Q21*G21) -> 0 | S21: =IF(D21="","",_xlfn.XLOOKUP(A21,'6'!A:A,'6'!D:D,IF($Q$6=0,0,"ERROR"))) -> 0 | T21: =IF(G21="","",S21*G21) -> 0 | U21: =IF(D21="","",_xlfn.XLOOKUP(A21,'7'!A:A,'7'!D:D,IF($U$6=0,0,"ERROR"))) -> 3 | V21: =IF(G21="","",U21*G21) -> 642.6 | W21: =IF(D21="","",_xlfn.XLOOKUP(A21,'8'!A:A,'8'!D:D,IF($U$6=0,0,"ERROR"))) -> 0 | X21: =IF(G21="","",W21*G21) -> 0 | Y21: =IF(D21="","",_xlfn.XLOOKUP(A21,'9'!A:A,'9'!D:D,IF($U$6=0,0,"ERROR"))) -> 3 | Z21: =IF(G21="","",Y21*G21) -> 642.6 | AA21: =IF(D21="","",_xlfn.XLOOKUP(A21,'10'!A:A,'10'!D:D,IF($U$6=0,0,"ERROR"))) -> 3 | AB21: =IF(G21="","",AA21*G21) -> 642.6 | AC21: =IF(D21="","",_xlfn.XLOOKUP(A21,'11'!A:A,'11'!D:D,IF($U$6=0,0,"ERROR"))) -> 2 | AD21: =IF(G21="","",AC21*G21) -> 428.4 | AE21: =IF(D21="","",_xlfn.XLOOKUP(A21,'12'!A:A,'12'!D:D,IF($U$6=0,0,"ERROR"))) -> 0 | AF21: =IF(G21="","",AE21*G21) -> 0 | AG21: =IF(D21="","",_xlfn.XLOOKUP(A21,'13'!A:A,'13'!D:D,IF($U$6=0,0,"ERROR"))) -> 0 | AH21: =IF(G21="","",AG21*G21) -> 0 | AI21: =IF(D21="","",_xlfn.XLOOKUP(A21,'14'!A:A,'14'!D:D,IF($U$6=0,0,"ERROR"))) -> 0 | AJ21: =IF(G21="","",AI21*G21) -> 0 | AM21: =IF(D21="","",Q21+O21+M21+K21+I21+S21+U21+W21+Y21+AA21+AC21+AE21+AG21+AI21) -> 17 | AN21: =IF(D21="","",R21+P21+N21+L21+J21+T21+V21+X21+Z21+AB21+AD21+AH21+AF21+AJ21) -> 3641.4 | AO21: =IF(AN21="","",IF(AM21*G21=AN21,"הכל טוב","לא טוב")) -> הכל טוב
A22: 12.011.9017 | B22: פירוק חלונות אלומיניום ומשקופיהם בשטח של מעל 3 מ"ר ועד 5 מ"ר | C22: יח' | D22: 310 | E22: =IF(D22="","",D22*0.15) -> 46.5 | F22: =IF(D22="","",D22*0.05) -> 15.5 | G22: =IF(D22="","",D22*1.05*0.85) -> 276.675 | J22: =IF(D22="","",I22*G22) -> 0 | L22: =IF(G22="","",K22*G22) -> 0 | M22: =IF(D22="","",_xlfn.XLOOKUP(A22,'3'!A:A,'3'!D:D,IF($M$6=0,0,"ERROR"))) -> 0 | N22: =IF(G22="","",M22*G22) -> 0 | O22: =IF(D22="","",_xlfn.XLOOKUP(A22,'4'!A:A,'4'!D:D,IF($O$6=0,0,"ERROR"))) -> 0 | P22: =IF(G22="","",O22*G22) -> 0 | Q22: =IF(D22="","",_xlfn.XLOOKUP(A22,'5'!A:A,'5'!D:D,IF($Q$6=0,0,"ERROR"))) -> 7 | R22: =IF(G22="","",Q22*G22) -> 1936.725 | S22: =IF(D22="","",_xlfn.XLOOKUP(A22,'6'!A:A,'6'!D:D,IF($Q$6=0,0,"ERROR"))) -> 3 | T22: =IF(G22="","",S22*G22) -> 830.025 | U22: =IF(D22="","",_xlfn.XLOOKUP(A22,'7'!A:A,'7'!D:D,IF($U$6=0,0,"ERROR"))) -> 0 | V22: =IF(G22="","",U22*G22) -> 0 | W22: =IF(D22="","",_xlfn.XLOOKUP(A22,'8'!A:A,'8'!D:D,IF($U$6=0,0,"ERROR"))) -> 6 | X22: =IF(G22="","",W22*G22) -> 1660.05 | Y22: =IF(D22="","",_xlfn.XLOOKUP(A22,'9'!A:A,'9'!D:D,IF($U$6=0,0,"ERROR"))) -> 1 | Z22: =IF(G22="","",Y22*G22) -> 276.675 | AA22: =IF(D22="","",_xlfn.XLOOKUP(A22,'10'!A:A,'10'!D:D,IF($U$6=0,0,"ERROR"))) -> 5 | AB22: =IF(G22="","",AA22*G22) -> 1383.375 | AC22: =IF(D22="","",_xlfn.XLOOKUP(A22,'11'!A:A,'11'!D:D,IF($U$6=0,0,"ERROR"))) -> 1 | AD22: =IF(G22="","",AC22*G22) -> 276.675 | AE22: =IF(D22="","",_xlfn.XLOOKUP(A22,'12'!A:A,'12'!D:D,IF($U$6=0,0,"ERROR"))) -> 2 | AF22: =IF(G22="","",AE22*G22) -> 553.35 | AG22: =IF(D22="","",_xlfn.XLOOKUP(A22,'13'!A:A,'13'!D:D,IF($U$6=0,0,"ERROR"))) -> 1 | AH22: =IF(G22="","",AG22*G22) -> 276.675 | AI22: =IF(D22="","",_xlfn.XLOOKUP(A22,'14'!A:A,'14'!D:D,IF($U$6=0,0,"ERROR"))) -> 0 | AJ22: =IF(G22="","",AI22*G22) -> 0 | AM22: =IF(D22="","",Q22+O22+M22+K22+I22+S22+U22+W22+Y22+AA22+AC22+AE22+AG22+AI22) -> 26 | AN22: =IF(D22="","",R22+P22+N22+L22+J22+T22+V22+X22+Z22+AB22+AD22+AH22+AF22+AJ22) -> 7193.55 | AO22: =IF(AN22="","",IF(AM22*G22=AN22,"הכל טוב","לא טוב")) -> הכל טוב
A23: 12.014 | B23: חלון אלומיניום ציר צד וחלון דו-צירי סב-נטוי (DREH-KIPP) | E23: =IF(D23="","",D23*0.15) | F23: =IF(D23="","",D23*0.05) | G23: =IF(D23="","",D23*1.05*0.85) | J23: =IF(D23="","",I23*G23) | L23: =IF(G23="","",K23*G23) | M23: =IF(D23="","",_xlfn.XLOOKUP(A23,'3'!A:A,'3'!D:D,IF($M$6=0,0,"ERROR"))) | N23: =IF(G23="","",M23*G23) | O23: =IF(D23="","",_xlfn.XLOOKUP(A23,'4'!A:A,'4'!D:D,IF($O$6=0,0,"ERROR"))) | P23: =IF(G23="","",O23*G23) | Q23: =IF(D23="","",_xlfn.XLOOKUP(A23,'5'!A:A,'5'!D:D,IF($Q$6=0,0,"ERROR"))) | R23: =IF(G23="","",Q23*G23) | S23: =IF(D23="","",_xlfn.XLOOKUP(A23,'6'!A:A,'6'!D:D,IF($Q$6=0,0,"ERROR"))) | T23: =IF(G23="","",S23*G23) | U23: =IF(D23="","",_xlfn.XLOOKUP(A23,'7'!A:A,'7'!D:D,IF($U$6=0,0,"ERROR"))) | V23: =IF(G23="","",U23*G23) | W23: =IF(D23="","",_xlfn.XLOOKUP(A23,'8'!A:A,'8'!D:D,IF($U$6=0,0,"ERROR"))) | X23: =IF(G23="","",W23*G23) | Y23: =IF(D23="","",_xlfn.XLOOKUP(A23,'9'!A:A,'9'!D:D,IF($U$6=0,0,"ERROR"))) | Z23: =IF(G23="","",Y23*G23) | AA23: =IF(D23="","",_xlfn.XLOOKUP(A23,'10'!A:A,'10'!D:D,IF($U$6=0,0,"ERROR"))) | AB23: =IF(G23="","",AA23*G23) | AC23: =IF(D23="","",_xlfn.XLOOKUP(A23,'11'!A:A,'11'!D:D,IF($U$6=0,0,"ERROR"))) | AD23: =IF(G23="","",AC23*G23) | AE23: =IF(D23="","",_xlfn.XLOOKUP(A23,'12'!A:A,'12'!D:D,IF($U$6=0,0,"ERROR"))) | AF23: =IF(G23="","",AE23*G23) | AG23: =IF(D23="","",_xlfn.XLOOKUP(A23,'13'!A:A,'13'!D:D,IF($U$6=0,0,"ERROR"))) | AH23: =IF(G23="","",AG23*G23) | AI23: =IF(D23="","",_xlfn.XLOOKUP(A23,'14'!A:A,'14'!D:D,IF($U$6=0,0,"ERROR"))) | AJ23: =IF(G23="","",AI23*G23) | AM23: =IF(D23="","",Q23+O23+M23+K23+I23+S23+U23+W23+Y23+AA23+AC23+AE23+AG23+AI23) | AN23: =IF(D23="","",R23+P23+N23+L23+J23+T23+V23+X23+Z23+AB23+AD23+AH23+AF23+AJ23) | AO23: =IF(AN23="","",IF(AM23*G23=AN23,"הכל טוב","לא טוב"))
A24: 12.014.0400 | B24: חלון ציר-צד מאולגן/צבוע כדוגמת קליל קלאסי 4500 או ש"ע, זכוכית שקופה בידודית 5+6+6 מ"מ, בשטח מעל 0.6 מ"ר ועד 1.0 מ"ר | C24: מ"ר | D24: 2220 | E24: =IF(D24="","",D24*0.15) -> 333 | F24: =IF(D24="","",D24*0.05) -> 111 | G24: =IF(D24="","",D24*1.05*0.85) -> 1981.35 | J24: =IF(D24="","",I24*G24) -> 0 | L24: =IF(G24="","",K24*G24) -> 0 | M24: =IF(D24="","",_xlfn.XLOOKUP(A24,'3'!A:A,'3'!D:D,IF($M$6=0,0,"ERROR"))) -> 0 | N24: =IF(G24="","",M24*G24) -> 0 | O24: =IF(D24="","",_xlfn.XLOOKUP(A24,'4'!A:A,'4'!D:D,IF($O$6=0,0,"ERROR"))) -> 0 | P24: =IF(G24="","",O24*G24) -> 0 | Q24: =IF(D24="","",_xlfn.XLOOKUP(A24,'5'!A:A,'5'!D:D,IF($Q$6=0,0,"ERROR"))) -> 0 | R24: =IF(G24="","",Q24*G24) -> 0 | S24: =IF(D24="","",_xlfn.XLOOKUP(A24,'6'!A:A,'6'!D:D,IF($Q$6=0,0,"ERROR"))) -> 0 | T24: =IF(G24="","",S24*G24) -> 0 | U24: =IF(D24="","",_xlfn.XLOOKUP(A24,'7'!A:A,'7'!D:D,IF($U$6=0,0,"ERROR"))) -> 0 | V24: =IF(G24="","",U24*G24) -> 0 | W24: =IF(D24="","",_xlfn.XLOOKUP(A24,'8'!A:A,'8'!D:D,IF($U$6=0,0,"ERROR"))) -> 0 | X24: =IF(G24="","",W24*G24) -> 0 | Y24: =IF(D24="","",_xlfn.XLOOKUP(A24,'9'!A:A,'9'!D:D,IF($U$6=0,0,"ERROR"))) -> 0 | Z24: =IF(G24="","",Y24*G24) -> 0 | AA24: =IF(D24="","",_xlfn.XLOOKUP(A24,'10'!A:A,'10'!D:D,IF($U$6=0,0,"ERROR"))) -> 0 | AB24: =IF(G24="","",AA24*G24) -> 0 | AC24: =IF(D24="","",_xlfn.XLOOKUP(A24,'11'!A:A,'11'!D:D,IF($U$6=0,0,"ERROR"))) -> 0 | AD24: =IF(G24="","",AC24*G24) -> 0 | AE24: =IF(D24="","",_xlfn.XLOOKUP(A24,'12'!A:A,'12'!D:D,IF($U$6=0,0,"ERROR"))) -> 0 | AF24: =IF(G24="","",AE24*G24) -> 0 | AG24: =IF(D24="","",_xlfn.XLOOKUP(A24,'13'!A:A,'13'!D:D,IF($U$6=0,0,"ERROR"))) -> 3.33 | AH24: =IF(G24="","",AG24*G24) -> 6597.8955 | AI24: =IF(D24="","",_xlfn.XLOOKUP(A24,'14'!A:A,'14'!D:D,IF($U$6=0,0,"ERROR"))) -> 0 | AJ24: =IF(G24="","",AI24*G24) -> 0 | AM24: =IF(D24="","",Q24+O24+M24+K24+I24+S24+U24+W24+Y24+AA24+AC24+AE24+AG24+AI24) -> 3.33 | AN24: =IF(D24="","",R24+P24+N24+L24+J24+T24+V24+X24+Z24+AB24+AD24+AH24+AF24+AJ24) -> 6597.8955 | AO24: =IF(AN24="","",IF(AM24*G24=AN24,"הכל טוב","לא טוב")) -> הכל טוב
A25: 12.014.0650 | B25: חלון ציר-צד מאולגן/צבוע כדוגמת קליל קלאסי 4500 או ש"ע, זכוכית שקופה בידודית 5+6+6 מ"מ, בשטח מעל 0.6 מ"ר ועד 1.0 מ"ר | C25: מ"ר | D25: 2790 | E25: =IF(D25="","",D25*0.15) -> 418.5 | F25: =IF(D25="","",D25*0.05) -> 139.5 | G25: =IF(D25="","",D25*1.05*0.85) -> 2490.075 | J25: =IF(D25="","",I25*G25) -> 0 | L25: =IF(G25="","",K25*G25) -> 0 | M25: =IF(D25="","",_xlfn.XLOOKUP(A25,'3'!A:A,'3'!D:D,IF($M$6=0,0,"ERROR"))) -> 0 | N25: =IF(G25="","",M25*G25) -> 0 | O25: 0 | P25: =IF(G25="","",O25*G25) -> 0 | Q25: 0 | R25: =IF(G25="","",Q25*G25) -> 0 | S25: =IF(D25="","",_xlfn.XLOOKUP(A25,'6'!A:A,'6'!D:D,IF($Q$6=0,0,"ERROR"))) -> 0 | T25: =IF(G25="","",S25*G25) -> 0 | U25: 0 | V25: =IF(G25="","",U25*G25) -> 0 | W25: =IF(D25="","",_xlfn.XLOOKUP(A25,'8'!A:A,'8'!D:D,IF($U$6=0,0,"ERROR"))) -> 0 | X25: =IF(G25="","",W25*G25) -> 0 | Y25: 0 | Z25: =IF(G25="","",Y25*G25) -> 0 | AA25: =IF(D25="","",_xlfn.XLOOKUP(A25,'10'!A:A,'10'!D:D,IF($U$6=0,0,"ERROR"))) -> 0 | AB25: =IF(G25="","",AA25*G25) -> 0 | AC25: 0 | AD25: =IF(G25="","",AC25*G25) -> 0 | AE25: 0 | AF25: =IF(G25="","",AE25*G25) -> 0 | AG25: 0 | AH25: =IF(G25="","",AG25*G25) -> 0 | AI25: 0 | AJ25: =IF(G25="","",AI25*G25) -> 0 | AM25: =IF(D25="","",Q25+O25+M25+K25+I25+S25+U25+W25+Y25+AA25+AC25+AE25+AG25+AI25) -> 0 | AN25: =IF(D25="","",R25+P25+N25+L25+J25+T25+V25+X25+Z25+AB25+AD25+AH25+AF25+AJ25) -> 0 | AO25: =IF(AN25="","",IF(AM25*G25=AN25,"הכל טוב","לא טוב")) -> הכל טוב
A26: 12.014.0660 | B26: חלון דו-צירי סב נטוי (דריי קיפ), מאולגן/צבוע כדוגמת קליל קלאסי 4500 או ש"ע, זכוכית שקופה בידודית מחוסמת דו צדדי 6+10+8 מ"מ, בשטח מעל 1.0 מ"ר ועד 2.0 מ"ר | C26: מ"ר | D26: 2700 | E26: =IF(D26="","",D26*0.15) -> 405 | F26: =IF(D26="","",D26*0.05) -> 135 | G26: =IF(D26="","",D26*1.05*0.85) -> 2409.75 | J26: =IF(D26="","",I26*G26) -> 0 | L26: =IF(G26="","",K26*G26) -> 0 | M26: =IF(D26="","",_xlfn.XLOOKUP(A26,'3'!A:A,'3'!D:D,IF($M$6=0,0,"ERROR"))) -> 0 | N26: =IF(G26="","",M26*G26) -> 0 | O26: =IF(D26="","",_xlfn.XLOOKUP(A26,'4'!A:A,'4'!D:D,IF($O$6=0,0,"ERROR"))) -> 0 | P26: =IF(G26="","",O26*G26) -> 0 | Q26: =IF(D26="","",_xlfn.XLOOKUP(A26,'5'!A:A,'5'!D:D,IF($Q$6=0,0,"ERROR"))) -> 0 | R26: =IF(G26="","",Q26*G26) -> 0 | S26: =IF(D26="","",_xlfn.XLOOKUP(A26,'6'!A:A,'6'!D:D,IF($Q$6=0,0,"ERROR"))) -> 0 | T26: =IF(G26="","",S26*G26) -> 0 | U26: =IF(D26="","",_xlfn.XLOOKUP(A26,'7'!A:A,'7'!D:D,IF($U$6=0,0,"ERROR"))) -> 0 | V26: =IF(G26="","",U26*G26) -> 0 | W26: =IF(D26="","",_xlfn.XLOOKUP(A26,'8'!A:A,'8'!D:D,IF($U$6=0,0,"ERROR"))) -> 0 | X26: =IF(G26="","",W26*G26) -> 0 | Y26: =IF(D26="","",_xlfn.XLOOKUP(A26,'9'!A:A,'9'!D:D,IF($U$6=0,0,"ERROR"))) -> 0 | Z26: =IF(G26="","",Y26*G26) -> 0 | AA26: =IF(D26="","",_xlfn.XLOOKUP(A26,'10'!A:A,'10'!D:D,IF($U$6=0,0,"ERROR"))) -> 0 | AB26: =IF(G26="","",AA26*G26) -> 0 | AC26: =IF(D26="","",_xlfn.XLOOKUP(A26,'11'!A:A,'11'!D:D,IF($U$6=0,0,"ERROR"))) -> 0 | AD26: =IF(G26="","",AC26*G26) -> 0 | AE26: =IF(D26="","",_xlfn.XLOOKUP(A26,'12'!A:A,'12'!D:D,IF($U$6=0,0,"ERROR"))) -> 0 | AF26: =IF(G26="","",AE26*G26) -> 0 | AG26: =IF(D26="","",_xlfn.XLOOKUP(A26,'13'!A:A,'13'!D:D,IF($U$6=0,0,"ERROR"))) -> 0 | AH26: =IF(G26="","",AG26*G26) -> 0 | AI26: =IF(D26="","",_xlfn.XLOOKUP(A26,'14'!A:A,'14'!D:D,IF($U$6=0,0,"ERROR"))) -> 0 | AJ26: =IF(G26="","",AI26*G26) -> 0 | AM26: =IF(D26="","",Q26+O26+M26+K26+I26+S26+U26+W26+Y26+AA26+AC26+AE26+AG26+AI26) -> 0 | AN26: =IF(D26="","",R26+P26+N26+L26+J26+T26+V26+X26+Z26+AB26+AD26+AH26+AF26+AJ26) -> 0 | AO26: =IF(AN26="","",IF(AM26*G26=AN26,"הכל טוב","לא טוב")) -> הכל טוב
A27: 12.016 | B27: חלון אלומיניום קיפ וחלון קבוע | E27: =IF(D27="","",D27*0.15) | F27: =IF(D27="","",D27*0.05) | G27: =IF(D27="","",D27*1.05*0.85) | J27: =IF(D27="","",I27*G27) | L27: =IF(G27="","",K27*G27) | M27: =IF(D27="","",_xlfn.XLOOKUP(A27,'3'!A:A,'3'!D:D,IF($M$6=0,0,"ERROR"))) | N27: =IF(G27="","",M27*G27) | O27: =IF(D27="","",_xlfn.XLOOKUP(A27,'4'!A:A,'4'!D:D,IF($O$6=0,0,"ERROR"))) | P27: =IF(G27="","",O27*G27) | Q27: =IF(D27="","",_xlfn.XLOOKUP(A27,'5'!A:A,'5'!D:D,IF($Q$6=0,0,"ERROR"))) | R27: =IF(G27="","",Q27*G27) | S27: =IF(D27="","",_xlfn.XLOOKUP(A27,'6'!A:A,'6'!D:D,IF($Q$6=0,0,"ERROR"))) | T27: =IF(G27="","",S27*G27) | U27: =IF(D27="","",_xlfn.XLOOKUP(A27,'7'!A:A,'7'!D:D,IF($U$6=0,0,"ERROR"))) | V27: =IF(G27="","",U27*G27) | W27: =IF(D27="","",_xlfn.XLOOKUP(A27,'8'!A:A,'8'!D:D,IF($U$6=0,0,"ERROR"))) | X27: =IF(G27="","",W27*G27) | Y27: =IF(D27="","",_xlfn.XLOOKUP(A27,'9'!A:A,'9'!D:D,IF($U$6=0,0,"ERROR"))) | Z27: =IF(G27="","",Y27*G27) | AA27: =IF(D27="","",_xlfn.XLOOKUP(A27,'10'!A:A,'10'!D:D,IF($U$6=0,0,"ERROR"))) | AB27: =IF(G27="","",AA27*G27) | AC27: =IF(D27="","",_xlfn.XLOOKUP(A27,'11'!A:A,'11'!D:D,IF($U$6=0,0,"ERROR"))) | AD27: =IF(G27="","",AC27*G27) | AE27: =IF(D27="","",_xlfn.XLOOKUP(A27,'12'!A:A,'12'!D:D,IF($U$6=0,0,"ERROR"))) | AF27: =IF(G27="","",AE27*G27) | AG27: =IF(D27="","",_xlfn.XLOOKUP(A27,'13'!A:A,'13'!D:D,IF($U$6=0,0,"ERROR"))) | AH27: =IF(G27="","",AG27*G27) | AI27: =IF(D27="","",_xlfn.XLOOKUP(A27,'14'!A:A,'14'!D:D,IF($U$6=0,0,"ERROR"))) | AJ27: =IF(G27="","",AI27*G27) | AM27: =IF(D27="","",Q27+O27+M27+K27+I27+S27+U27+W27+Y27+AA27+AC27+AE27+AG27+AI27) | AN27: =IF(D27="","",R27+P27+N27+L27+J27+T27+V27+X27+Z27+AB27+AD27+AH27+AF27+AJ27) | AO27: =IF(AN27="","",IF(AM27*G27=AN27,"הכל טוב","לא טוב"))
A28: 12.016.0600 | B28: חלון קבוע כדוגמת קליל קלאסי 4500 או ש"ע, זכוכית שקופה בידודית 5+6+6 מ"מ, בשטח מעל 0.6 מ"ר ועד 1.0 מ"ר | C28: יח' | D28: 1310 | E28: =IF(D28="","",D28*0.15) -> 196.5 | F28: =IF(D28="","",D28*0.05) -> 65.5 | G28: =IF(D28="","",D28*1.05*0.85) -> 1169.175 | J28: =IF(D28="","",I28*G28) -> 0 | L28: =IF(G28="","",K28*G28) -> 0 | M28: =IF(D28="","",_xlfn.XLOOKUP(A28,'3'!A:A,'3'!D:D,IF($M$6=0,0,"ERROR"))) -> 0 | N28: =IF(G28="","",M28*G28) -> 0 | O28: =IF(D28="","",_xlfn.XLOOKUP(A28,'4'!A:A,'4'!D:D,IF($O$6=0,0,"ERROR"))) -> 0 | P28: =IF(G28="","",O28*G28) -> 0 | Q28: =IF(D28="","",_xlfn.XLOOKUP(A28,'5'!A:A,'5'!D:D,IF($Q$6=0,0,"ERROR"))) -> 0 | R28: =IF(G28="","",Q28*G28) -> 0 | S28: =IF(D28="","",_xlfn.XLOOKUP(A28,'6'!A:A,'6'!D:D,IF($Q$6=0,0,"ERROR"))) -> 0 | T28: =IF(G28="","",S28*G28) -> 0 | U28: =IF(D28="","",_xlfn.XLOOKUP(A28,'7'!A:A,'7'!D:D,IF($U$6=0,0,"ERROR"))) -> 0 | V28: =IF(G28="","",U28*G28) -> 0 | W28: =IF(D28="","",_xlfn.XLOOKUP(A28,'8'!A:A,'8'!D:D,IF($U$6=0,0,"ERROR"))) -> 0 | X28: =IF(G28="","",W28*G28) -> 0 | Y28: =IF(D28="","",_xlfn.XLOOKUP(A28,'9'!A:A,'9'!D:D,IF($U$6=0,0,"ERROR"))) -> 0 | Z28: =IF(G28="","",Y28*G28) -> 0 | AA28: =IF(D28="","",_xlfn.XLOOKUP(A28,'10'!A:A,'10'!D:D,IF($U$6=0,0,"ERROR"))) -> 0 | AB28: =IF(G28="","",AA28*G28) -> 0 | AC28: =IF(D28="","",_xlfn.XLOOKUP(A28,'11'!A:A,'11'!D:D,IF($U$6=0,0,"ERROR"))) -> 0 | AD28: =IF(G28="","",AC28*G28) -> 0 | AE28: =IF(D28="","",_xlfn.XLOOKUP(A28,'12'!A:A,'12'!D:D,IF($U$6=0,0,"ERROR"))) -> 0 | AF28: =IF(G28="","",AE28*G28) -> 0 | AG28: =IF(D28="","",_xlfn.XLOOKUP(A28,'13'!A:A,'13'!D:D,IF($U$6=0,0,"ERROR"))) -> 0 | AH28: =IF(G28="","",AG28*G28) -> 0 | AI28: =IF(D28="","",_xlfn.XLOOKUP(A28,'14'!A:A,'14'!D:D,IF($U$6=0,0,"ERROR"))) -> 0 | AJ28: =IF(G28="","",AI28*G28) -> 0 | AM28: =IF(D28="","",Q28+O28+M28+K28+I28+S28+U28+W28+Y28+AA28+AC28+AE28+AG28+AI28) -> 0 | AN28: =IF(D28="","",R28+P28+N28+L28+J28+T28+V28+X28+Z28+AB28+AD28+AH28+AF28+AJ28) -> 0 | AO28: =IF(AN28="","",IF(AM28*G28=AN28,"הכל טוב","לא טוב")) -> הכל טוב
A29: 12.016.0610 | B29: חלון קבוע כדוגמת קליל קלאסי 4500 או ש"ע, זכוכית שקופה בידודית 5+6+6 מ"מ, בשטח מעל 1.0 מ"ר ועד 2.0 מ"ר | C29: יח' | D29: 2090 | E29: =IF(D29="","",D29*0.15) -> 313.5 | F29: =IF(D29="","",D29*0.05) -> 104.5 | G29: =IF(D29="","",D29*1.05*0.85) -> 1865.325 | J29: =IF(D29="","",I29*G29) -> 0 | L29: =IF(G29="","",K29*G29) -> 0 | M29: =IF(D29="","",_xlfn.XLOOKUP(A29,'3'!A:A,'3'!D:D,IF($M$6=0,0,"ERROR"))) -> 0 | N29: =IF(G29="","",M29*G29) -> 0 | O29: =IF(D29="","",_xlfn.XLOOKUP(A29,'4'!A:A,'4'!D:D,IF($O$6=0,0,"ERROR"))) -> 0 | P29: =IF(G29="","",O29*G29) -> 0 | Q29: =IF(D29="","",_xlfn.XLOOKUP(A29,'5'!A:A,'5'!D:D,IF($Q$6=0,0,"ERROR"))) -> 0 | R29: =IF(G29="","",Q29*G29) -> 0 | S29: =IF(D29="","",_xlfn.XLOOKUP(A29,'6'!A:A,'6'!D:D,IF($Q$6=0,0,"ERROR"))) -> 0 | T29: =IF(G29="","",S29*G29) -> 0 | U29: =IF(D29="","",_xlfn.XLOOKUP(A29,'7'!A:A,'7'!D:D,IF($U$6=0,0,"ERROR"))) -> 0 | V29: =IF(G29="","",U29*G29) -> 0 | W29: =IF(D29="","",_xlfn.XLOOKUP(A29,'8'!A:A,'8'!D:D,IF($U$6=0,0,"ERROR"))) -> 0 | X29: =IF(G29="","",W29*G29) -> 0 | Y29: =IF(D29="","",_xlfn.XLOOKUP(A29,'9'!A:A,'9'!D:D,IF($U$6=0,0,"ERROR"))) -> 0 | Z29: =IF(G29="","",Y29*G29) -> 0 | AA29: =IF(D29="","",_xlfn.XLOOKUP(A29,'10'!A:A,'10'!D:D,IF($U$6=0,0,"ERROR"))) -> 0 | AB29: =IF(G29="","",AA29*G29) -> 0 | AC29: =IF(D29="","",_xlfn.XLOOKUP(A29,'11'!A:A,'11'!D:D,IF($U$6=0,0,"ERROR"))) -> 0 | AD29: =IF(G29="","",AC29*G29) -> 0 | AE29: =IF(D29="","",_xlfn.XLOOKUP(A29,'12'!A:A,'12'!D:D,IF($U$6=0,0,"ERROR"))) -> 0 | AF29: =IF(G29="","",AE29*G29) -> 0 | AG29: =IF(D29="","",_xlfn.XLOOKUP(A29,'13'!A:A,'13'!D:D,IF($U$6=0,0,"ERROR"))) -> 0 | AH29: =IF(G29="","",AG29*G29) -> 0 | AI29: =IF(D29="","",_xlfn.XLOOKUP(A29,'14'!A:A,'14'!D:D,IF($U$6=0,0,"ERROR"))) -> 0 | AJ29: =IF(G29="","",AI29*G29) -> 0 | AM29: =IF(D29="","",Q29+O29+M29+K29+I29+S29+U29+W29+Y29+AA29+AC29+AE29+AG29+AI29) -> 0 | AN29: =IF(D29="","",R29+P29+N29+L29+J29+T29+V29+X29+Z29+AB29+AD29+AH29+AF29+AJ29) -> 0 | AO29: =IF(AN29="","",IF(AM29*G29=AN29,"הכל טוב","לא טוב")) -> הכל טוב
B30: סה"כ לחלון אלומיניום קיפ וחלון קבוע | E30: =IF(D30="","",D30*0.15) | F30: =IF(D30="","",D30*0.05) | G30: =IF(D30="","",D30*1.05*0.85) | J30: =IF(D30="","",I30*G30) | L30: =IF(G30="","",K30*G30) | M30: =IF(D30="","",_xlfn.XLOOKUP(A30,'3'!A:A,'3'!D:D,IF($M$6=0,0,"ERROR"))) | N30: =IF(G30="","",M30*G30) | O30: =IF(D30="","",_xlfn.XLOOKUP(A30,'4'!A:A,'4'!D:D,IF($O$6=0,0,"ERROR"))) | P30: =IF(G30="","",O30*G30) | Q30: =IF(D30="","",_xlfn.XLOOKUP(A30,'5'!A:A,'5'!D:D,IF($Q$6=0,0,"ERROR"))) | R30: =IF(G30="","",Q30*G30) | S30: =IF(D30="","",_xlfn.XLOOKUP(A30,'6'!A:A,'6'!D:D,IF($Q$6=0,0,"ERROR"))) | T30: =IF(G30="","",S30*G30) | U30: =IF(D30="","",_xlfn.XLOOKUP(A30,'7'!A:A,'7'!D:D,IF($U$6=0,0,"ERROR"))) | V30: =IF(G30="","",U30*G30) | W30: =IF(D30="","",_xlfn.XLOOKUP(A30,'8'!A:A,'8'!D:D,IF($U$6=0,0,"ERROR"))) | X30: =IF(G30="","",W30*G30) | Y30: =IF(D30="","",_xlfn.XLOOKUP(A30,'9'!A:A,'9'!D:D,IF($U$6=0,0,"ERROR"))) | Z30: =IF(G30="","",Y30*G30) | AA30: =IF(D30="","",_xlfn.XLOOKUP(A30,'10'!A:A,'10'!D:D,IF($U$6=0,0,"ERROR"))) | AB30: =IF(G30="","",AA30*G30) | AC30: =IF(D30="","",_xlfn.XLOOKUP(A30,'11'!A:A,'11'!D:D,IF($U$6=0,0,"ERROR"))) | AD30: =IF(G30="","",AC30*G30) | AE30: =IF(D30="","",_xlfn.XLOOKUP(A30,'12'!A:A,'12'!D:D,IF($U$6=0,0,"ERROR"))) | AF30: =IF(G30="","",AE30*G30) | AG30: =IF(D30="","",_xlfn.XLOOKUP(A30,'13'!A:A,'13'!D:D,IF($U$6=0,0,"ERROR"))) | AH30: =IF(G30="","",AG30*G30) | AI30: =IF(D30="","",_xlfn.XLOOKUP(A30,'14'!A:A,'14'!D:D,IF($U$6=0,0,"ERROR"))) | AJ30: =IF(G30="","",AI30*G30) | AM30: =IF(D30="","",Q30+O30+M30+K30+I30+S30+U30+W30+Y30+AA30+AC30+AE30+AG30+AI30) | AN30: =IF(D30="","",R30+P30+N30+L30+J30+T30+V30+X30+Z30+AB30+AD30+AH30+AF30+AJ30) | AO30: =IF(AN30="","",IF(AM30*G30=AN30,"הכל טוב","לא טוב"))
A31: 12.052 | B31: דלתות אלומיניום נגררות אגף על אגף (הזזה) של 3 אגפים ו-4 אגפים | E31: =IF(D31="","",D31*0.15) | F31: =IF(D31="","",D31*0.05) | G31: =IF(D31="","",D31*1.05*0.85) | J31: =IF(D31="","",I31*G31) | L31: =IF(G31="","",K31*G31) | M31: =IF(D31="","",_xlfn.XLOOKUP(A31,'3'!A:A,'3'!D:D,IF($M$6=0,0,"ERROR"))) | N31: =IF(G31="","",M31*G31) | O31: =IF(D31="","",_xlfn.XLOOKUP(A31,'4'!A:A,'4'!D:D,IF($O$6=0,0,"ERROR"))) | P31: =IF(G31="","",O31*G31) | Q31: =IF(D31="","",_xlfn.XLOOKUP(A31,'5'!A:A,'5'!D:D,IF($Q$6=0,0,"ERROR"))) | R31: =IF(G31="","",Q31*G31) | S31: =IF(D31="","",_xlfn.XLOOKUP(A31,'6'!A:A,'6'!D:D,IF($Q$6=0,0,"ERROR"))) | T31: =IF(G31="","",S31*G31) | U31: =IF(D31="","",_xlfn.XLOOKUP(A31,'7'!A:A,'7'!D:D,IF($U$6=0,0,"ERROR"))) | V31: =IF(G31="","",U31*G31) | W31: =IF(D31="","",_xlfn.XLOOKUP(A31,'8'!A:A,'8'!D:D,IF($U$6=0,0,"ERROR"))) | X31: =IF(G31="","",W31*G31) | Y31: =IF(D31="","",_xlfn.XLOOKUP(A31,'9'!A:A,'9'!D:D,IF($U$6=0,0,"ERROR"))) | Z31: =IF(G31="","",Y31*G31) | AA31: =IF(D31="","",_xlfn.XLOOKUP(A31,'10'!A:A,'10'!D:D,IF($U$6=0,0,"ERROR"))) | AB31: =IF(G31="","",AA31*G31) | AC31: =IF(D31="","",_xlfn.XLOOKUP(A31,'11'!A:A,'11'!D:D,IF($U$6=0,0,"ERROR"))) | AD31: =IF(G31="","",AC31*G31) | AE31: =IF(D31="","",_xlfn.XLOOKUP(A31,'12'!A:A,'12'!D:D,IF($U$6=0,0,"ERROR"))) | AF31: =IF(G31="","",AE31*G31) | AG31: =IF(D31="","",_xlfn.XLOOKUP(A31,'13'!A:A,'13'!D:D,IF($U$6=0,0,"ERROR"))) | AH31: =IF(G31="","",AG31*G31) | AI31: =IF(D31="","",_xlfn.XLOOKUP(A31,'14'!A:A,'14'!D:D,IF($U$6=0,0,"ERROR"))) | AJ31: =IF(G31="","",AI31*G31) | AM31: =IF(D31="","",Q31+O31+M31+K31+I31+S31+U31+W31+Y31+AA31+AC31+AE31+AG31+AI31) | AN31: =IF(D31="","",R31+P31+N31+L31+J31+T31+V31+X31+Z31+AB31+AD31+AH31+AF31+AJ31) | AO31: =IF(AN31="","",IF(AM31*G31=AN31,"הכל טוב","לא טוב"))
A32: 12.052.0020 | B32: דלת נגררת אגף על אגף של 3 אגפים ב-3 מסלולים מאולגנת/צבועה כדוגמת קליל קלאסי 7000 או ש"ע, זכוכית מחוסמת בעובי 6 מ"מ, בשטח מעל 6.0 מ"ר ועד 8.0 מ"ר | C32: מ"ר | D32: 1760 | E32: =IF(D32="","",D32*0.15) -> 264 | F32: =IF(D32="","",D32*0.05) -> 88 | G32: =IF(D32="","",D32*1.05*0.85) -> 1570.8 | J32: =IF(D32="","",I32*G32) -> 0 | L32: =IF(G32="","",K32*G32) -> 0 | M32: =IF(D32="","",_xlfn.XLOOKUP(A32,'3'!A:A,'3'!D:D,IF($M$6=0,0,"ERROR"))) -> 0 | N32: =IF(G32="","",M32*G32) -> 0 | O32: =IF(D32="","",_xlfn.XLOOKUP(A32,'4'!A:A,'4'!D:D,IF($O$6=0,0,"ERROR"))) -> 0 | P32: =IF(G32="","",O32*G32) -> 0 | Q32: =IF(D32="","",_xlfn.XLOOKUP(A32,'5'!A:A,'5'!D:D,IF($Q$6=0,0,"ERROR"))) -> 0 | R32: =IF(G32="","",Q32*G32) -> 0 | S32: =IF(D32="","",_xlfn.XLOOKUP(A32,'6'!A:A,'6'!D:D,IF($Q$6=0,0,"ERROR"))) -> 0 | T32: =IF(G32="","",S32*G32) -> 0 | U32: =IF(D32="","",_xlfn.XLOOKUP(A32,'7'!A:A,'7'!D:D,IF($U$6=0,0,"ERROR"))) -> 0 | V32: =IF(G32="","",U32*G32) -> 0 | W32: =IF(D32="","",_xlfn.XLOOKUP(A32,'8'!A:A,'8'!D:D,IF($U$6=0,0,"ERROR"))) -> 0 | X32: =IF(G32="","",W32*G32) -> 0 | Y32: =IF(D32="","",_xlfn.XLOOKUP(A32,'9'!A:A,'9'!D:D,IF($U$6=0,0,"ERROR"))) -> 0 | Z32: =IF(G32="","",Y32*G32) -> 0 | AA32: =IF(D32="","",_xlfn.XLOOKUP(A32,'10'!A:A,'10'!D:D,IF($U$6=0,0,"ERROR"))) -> 0 | AB32: =IF(G32="","",AA32*G32) -> 0 | AC32: =IF(D32="","",_xlfn.XLOOKUP(A32,'11'!A:A,'11'!D:D,IF($U$6=0,0,"ERROR"))) -> 6.325 | AD32: =IF(G32="","",AC32*G32) -> 9935.31 | AE32: =IF(D32="","",_xlfn.XLOOKUP(A32,'12'!A:A,'12'!D:D,IF($U$6=0,0,"ERROR"))) -> 0 | AF32: =IF(G32="","",AE32*G32) -> 0 | AG32: =IF(D32="","",_xlfn.XLOOKUP(A32,'13'!A:A,'13'!D:D,IF($U$6=0,0,"ERROR"))) -> 0 | AH32: =IF(G32="","",AG32*G32) -> 0 | AI32: =IF(D32="","",_xlfn.XLOOKUP(A32,'14'!A:A,'14'!D:D,IF($U$6=0,0,"ERROR"))) -> 0 | AJ32: =IF(G32="","",AI32*G32) -> 0 | AM32: =IF(D32="","",Q32+O32+M32+K32+I32+S32+U32+W32+Y32+AA32+AC32+AE32+AG32+AI32) -> 6.325 | AN32: =IF(D32="","",R32+P32+N32+L32+J32+T32+V32+X32+Z32+AB32+AD32+AH32+AF32+AJ32) -> 9935.31 | AO32: =IF(AN32="","",IF(AM32*G32=AN32,"הכל טוב","לא טוב")) -> הכל טוב
A33: 12.052.0070 | B33: דלת נגררת אגף על אגף של 3 אגפים ב-3 מסלולים מאולגנת/צבועה כדוגמת קליל קלאסי 9000 או ש"ע, זכוכית מחוסמת בעובי 6 מ"מ, בשטח מעל 6.0 מ"ר ועד 8.0 מ"ר | C33: מ"ר | D33: 1850 | E33: =IF(D33="","",D33*0.15) -> 277.5 | F33: =IF(D33="","",D33*0.05) -> 92.5 | G33: =IF(D33="","",D33*1.05*0.85) -> 1651.125 | J33: =IF(D33="","",I33*G33) -> 0 | L33: =IF(G33="","",K33*G33) -> 0 | M33: =IF(D33="","",_xlfn.XLOOKUP(A33,'3'!A:A,'3'!D:D,IF($M$6=0,0,"ERROR"))) -> 0 | N33: =IF(G33="","",M33*G33) -> 0 | O33: =IF(D33="","",_xlfn.XLOOKUP(A33,'4'!A:A,'4'!D:D,IF($O$6=0,0,"ERROR"))) -> 0 | P33: =IF(G33="","",O33*G33) -> 0 | Q33: =IF(D33="","",_xlfn.XLOOKUP(A33,'5'!A:A,'5'!D:D,IF($Q$6=0,0,"ERROR"))) -> 9.77 | R33: =IF(G33="","",Q33*G33) -> 16131.491 | S33: =IF(D33="","",_xlfn.XLOOKUP(A33,'6'!A:A,'6'!D:D,IF($Q$6=0,0,"ERROR"))) -> 7.88 | T33: =IF(G33="","",S33*G33) -> 13010.865 | U33: =IF(D33="","",_xlfn.XLOOKUP(A33,'7'!A:A,'7'!D:D,IF($U$6=0,0,"ERROR"))) -> 0 | V33: =IF(G33="","",U33*G33) -> 0 | W33: =IF(D33="","",_xlfn.XLOOKUP(A33,'8'!A:A,'8'!D:D,IF($U$6=0,0,"ERROR"))) -> 8.74 | X33: =IF(G33="","",W33*G33) -> 14430.833 | Y33: =IF(D33="","",_xlfn.XLOOKUP(A33,'9'!A:A,'9'!D:D,IF($U$6=0,0,"ERROR"))) -> 6.83 | Z33: =IF(G33="","",Y33*G33) -> 11277.184 | AA33: =IF(D33="","",_xlfn.XLOOKUP(A33,'10'!A:A,'10'!D:D,IF($U$6=0,0,"ERROR"))) -> 0 | AB33: =IF(G33="","",AA33*G33) -> 0 | AC33: =IF(D33="","",_xlfn.XLOOKUP(A33,'11'!A:A,'11'!D:D,IF($U$6=0,0,"ERROR"))) -> 0 | AD33: =IF(G33="","",AC33*G33) -> 0 | AE33: =IF(D33="","",_xlfn.XLOOKUP(A33,'12'!A:A,'12'!D:D,IF($U$6=0,0,"ERROR"))) -> 0 | AF33: =IF(G33="","",AE33*G33) -> 0 | AG33: =IF(D33="","",_xlfn.XLOOKUP(A33,'13'!A:A,'13'!D:D,IF($U$6=0,0,"ERROR"))) -> 6.9 | AH33: =IF(G33="","",AG33*G33) -> 11392.763 | AI33: =IF(D33="","",_xlfn.XLOOKUP(A33,'14'!A:A,'14'!D:D,IF($U$6=0,0,"ERROR"))) -> 7.54 | AJ33: =IF(G33="","",AI33*G33) -> 12449.483 | AM33: =IF(D33="","",Q33+O33+M33+K33+I33+S33+U33+W33+Y33+AA33+AC33+AE33+AG33+AI33) -> 47.66 | AN33: =IF(D33="","",R33+P33+N33+L33+J33+T33+V33+X33+Z33+AB33+AD33+AH33+AF33+AJ33) -> 78692.617 | AO33: =IF(AN33="","",IF(AM33*G33=AN33,"הכל טוב","לא טוב")) -> הכל טוב
A34: 12.052.0080 | B34: דלת נגררת אגף על אגף של 3 אגפים ב-3 מסלולים מאולגנת/צבועה כדוגמת קליל קלאסי 9000 או ש"ע, זכוכית מחוסמת בעובי 8 מ"מ, בשטח מעל 8.0 מ"ר ועד 10.0 מ"ר | C34: מ"ר | D34: 1680 | E34: =IF(D34="","",D34*0.15) -> 252 | F34: =IF(D34="","",D34*0.05) -> 84 | G34: =IF(D34="","",D34*1.05*0.85) -> 1499.4 | J34: =IF(D34="","",I34*G34) -> 0 | L34: =IF(G34="","",K34*G34) -> 0 | M34: =IF(D34="","",_xlfn.XLOOKUP(A34,'3'!A:A,'3'!D:D,IF($M$6=0,0,"ERROR"))) -> 8.4708 | N34: =IF(G34="","",M34*G34) -> 12701.118 | O34: =IF(D34="","",_xlfn.XLOOKUP(A34,'4'!A:A,'4'!D:D,IF($O$6=0,0,"ERROR"))) -> 0 | P34: =IF(G34="","",O34*G34) -> 0 | Q34: =IF(D34="","",_xlfn.XLOOKUP(A34,'5'!A:A,'5'!D:D,IF($Q$6=0,0,"ERROR"))) -> 0 | R34: =IF(G34="","",Q34*G34) -> 0 | S34: =IF(D34="","",_xlfn.XLOOKUP(A34,'6'!A:A,'6'!D:D,IF($Q$6=0,0,"ERROR"))) -> 0 | T34: =IF(G34="","",S34*G34) -> 0 | U34: =IF(D34="","",_xlfn.XLOOKUP(A34,'7'!A:A,'7'!D:D,IF($U$6=0,0,"ERROR"))) -> 8.736 | V34: =IF(G34="","",U34*G34) -> 13098.758 | W34: =IF(D34="","",_xlfn.XLOOKUP(A34,'8'!A:A,'8'!D:D,IF($U$6=0,0,"ERROR"))) -> 0 | X34: =IF(G34="","",W34*G34) -> 0 | Y34: =IF(D34="","",_xlfn.XLOOKUP(A34,'9'!A:A,'9'!D:D,IF($U$6=0,0,"ERROR"))) -> 0 | Z34: =IF(G34="","",Y34*G34) -> 0 | AA34: =IF(D34="","",_xlfn.XLOOKUP(A34,'10'!A:A,'10'!D:D,IF($U$6=0,0,"ERROR"))) -> 0 | AB34: =IF(G34="","",AA34*G34) -> 0 | AC34: =IF(D34="","",_xlfn.XLOOKUP(A34,'11'!A:A,'11'!D:D,IF($U$6=0,0,"ERROR"))) -> 0 | AD34: =IF(G34="","",AC34*G34) -> 0 | AE34: =IF(D34="","",_xlfn.XLOOKUP(A34,'12'!A:A,'12'!D:D,IF($U$6=0,0,"ERROR"))) -> 0 | AF34: =IF(G34="","",AE34*G34) -> 0 | AG34: =IF(D34="","",_xlfn.XLOOKUP(A34,'13'!A:A,'13'!D:D,IF($U$6=0,0,"ERROR"))) -> 0 | AH34: =IF(G34="","",AG34*G34) -> 0 | AI34: =IF(D34="","",_xlfn.XLOOKUP(A34,'14'!A:A,'14'!D:D,IF($U$6=0,0,"ERROR"))) -> 0 | AJ34: =IF(G34="","",AI34*G34) -> 0 | AM34: =IF(D34="","",Q34+O34+M34+K34+I34+S34+U34+W34+Y34+AA34+AC34+AE34+AG34+AI34) -> 17.2068 | AN34: =IF(D34="","",R34+P34+N34+L34+J34+T34+V34+X34+Z34+AB34+AD34+AH34+AF34+AJ34) -> 25799.876 | AO34: =IF(AN34="","",IF(AM34*G34=AN34,"הכל טוב","לא טוב")) -> הכל טוב
A35: 12.053 | B35: דלתות אלומיניום ציריות | E35: =IF(D35="","",D35*0.15) | F35: =IF(D35="","",D35*0.05) | G35: =IF(D35="","",D35*1.05*0.85) | J35: =IF(D35="","",I35*G35) | L35: =IF(G35="","",K35*G35) | M35: =IF(D35="","",_xlfn.XLOOKUP(A35,'3'!A:A,'3'!D:D,IF($M$6=0,0,"ERROR"))) | N35: =IF(G35="","",M35*G35) | O35: =IF(D35="","",_xlfn.XLOOKUP(A35,'4'!A:A,'4'!D:D,IF($O$6=0,0,"ERROR"))) | P35: =IF(G35="","",O35*G35) | Q35: =IF(D35="","",_xlfn.XLOOKUP(A35,'5'!A:A,'5'!D:D,IF($Q$6=0,0,"ERROR"))) | R35: =IF(G35="","",Q35*G35) | S35: =IF(D35="","",_xlfn.XLOOKUP(A35,'6'!A:A,'6'!D:D,IF($Q$6=0,0,"ERROR"))) | T35: =IF(G35="","",S35*G35) | U35: =IF(D35="","",_xlfn.XLOOKUP(A35,'7'!A:A,'7'!D:D,IF($U$6=0,0,"ERROR"))) | V35: =IF(G35="","",U35*G35) | W35: =IF(D35="","",_xlfn.XLOOKUP(A35,'8'!A:A,'8'!D:D,IF($U$6=0,0,"ERROR"))) | X35: =IF(G35="","",W35*G35) | Y35: =IF(D35="","",_xlfn.XLOOKUP(A35,'9'!A:A,'9'!D:D,IF($U$6=0,0,"ERROR"))) | Z35: =IF(G35="","",Y35*G35) | AA35: =IF(D35="","",_xlfn.XLOOKUP(A35,'10'!A:A,'10'!D:D,IF($U$6=0,0,"ERROR"))) | AB35: =IF(G35="","",AA35*G35) | AC35: =IF(D35="","",_xlfn.XLOOKUP(A35,'11'!A:A,'11'!D:D,IF($U$6=0,0,"ERROR"))) | AD35: =IF(G35="","",AC35*G35) | AE35: =IF(D35="","",_xlfn.XLOOKUP(A35,'12'!A:A,'12'!D:D,IF($U$6=0,0,"ERROR"))) | AF35: =IF(G35="","",AE35*G35) | AG35: =IF(D35="","",_xlfn.XLOOKUP(A35,'13'!A:A,'13'!D:D,IF($U$6=0,0,"ERROR"))) | AH35: =IF(G35="","",AG35*G35) | AI35: =IF(D35="","",_xlfn.XLOOKUP(A35,'14'!A:A,'14'!D:D,IF($U$6=0,0,"ERROR"))) | AJ35: =IF(G35="","",AI35*G35) | AM35: =IF(D35="","",Q35+O35+M35+K35+I35+S35+U35+W35+Y35+AA35+AC35+AE35+AG35+AI35) | AN35: =IF(D35="","",R35+P35+N35+L35+J35+T35+V35+X35+Z35+AB35+AD35+AH35+AF35+AJ35) | AO35: =IF(AN35="","",IF(AM35*G35=AN35,"הכל טוב","לא טוב"))
A36: 12.053.0200 | B36: דלת ציר אגף אחד מאולגנת/צבועה כדוגמת קליל 4500 או ש"ע, זכוכית מחוסמת בעובי 6 מ"מ, בשטח עד 2.0 מ"ר | C36: מ"ר | D36: 2850 | E36: =IF(D36="","",D36*0.15) -> 427.5 | F36: =IF(D36="","",D36*0.05) -> 142.5 | G36: =IF(D36="","",D36*1.05*0.85) -> 2543.625 | M36: =IF(D36="","",_xlfn.XLOOKUP(A36,'3'!A:A,'3'!D:D,IF($M$6=0,0,"ERROR"))) -> 0 | O36: =IF(D36="","",_xlfn.XLOOKUP(A36,'4'!A:A,'4'!D:D,IF($O$6=0,0,"ERROR"))) -> 0 | P36: =IF(G36="","",O36*G36) -> 0 | Q36: =IF(D36="","",_xlfn.XLOOKUP(A36,'5'!A:A,'5'!D:D,IF($Q$6=0,0,"ERROR"))) -> 0 | R36: =IF(G36="","",Q36*G36) -> 0 | S36: =IF(D36="","",_xlfn.XLOOKUP(A36,'6'!A:A,'6'!D:D,IF($Q$6=0,0,"ERROR"))) -> 0 | T36: =IF(G36="","",S36*G36) -> 0 | U36: =IF(D36="","",_xlfn.XLOOKUP(A36,'7'!A:A,'7'!D:D,IF($U$6=0,0,"ERROR"))) -> 0 | V36: =IF(G36="","",U36*G36) -> 0 | W36: =IF(D36="","",_xlfn.XLOOKUP(A36,'8'!A:A,'8'!D:D,IF($U$6=0,0,"ERROR"))) -> 0 | X36: =IF(G36="","",W36*G36) -> 0 | Y36: =IF(D36="","",_xlfn.XLOOKUP(A36,'9'!A:A,'9'!D:D,IF($U$6=0,0,"ERROR"))) -> 0 | Z36: =IF(G36="","",Y36*G36) -> 0 | AA36: =IF(D36="","",_xlfn.XLOOKUP(A36,'10'!A:A,'10'!D:D,IF($U$6=0,0,"ERROR"))) -> 0 | AB36: =IF(G36="","",AA36*G36) -> 0 | AC36: =IF(D36="","",_xlfn.XLOOKUP(A36,'11'!A:A,'11'!D:D,IF($U$6=0,0,"ERROR"))) -> 0 | AD36: =IF(G36="","",AC36*G36) -> 0 | AE36: =IF(D36="","",_xlfn.XLOOKUP(A36,'12'!A:A,'12'!D:D,IF($U$6=0,0,"ERROR"))) -> 0 | AF36: =IF(G36="","",AE36*G36) -> 0 | AG36: =IF(D36="","",_xlfn.XLOOKUP(A36,'13'!A:A,'13'!D:D,IF($U$6=0,0,"ERROR"))) -> 0 | AH36: =IF(G36="","",AG36*G36) -> 0 | AI36: =IF(D36="","",_xlfn.XLOOKUP(A36,'14'!A:A,'14'!D:D,IF($U$6=0,0,"ERROR"))) -> 0 | AJ36: =IF(G36="","",AI36*G36) -> 0 | AM36: =IF(D36="","",Q36+O36+M36+K36+I36+S36+U36+W36+Y36+AA36+AC36+AE36+AG36+AI36) -> 0 | AN36: =IF(D36="","",R36+P36+N36+L36+J36+T36+V36+X36+Z36+AB36+AD36+AH36+AF36+AJ36) -> 0 | AO36: =IF(AN36="","",IF(AM36*G36=AN36,"הכל טוב","לא טוב")) -> הכל טוב
A37: 12.053.0210 | B37: דלת ציר אגף אחד מאולגנת/צבועה כדוגמת קליל 4500 או ש"ע, זכוכית מחוסמת בעובי 6 מ"מ, בשטח מעל 2.0 מ"ר ועד 3.0 מ"ר | C37: מ"ר | D37: 2300 | E37: =IF(D37="","",D37*0.15) -> 345 | F37: =IF(D37="","",D37*0.05) -> 115 | G37: =IF(D37="","",D37*1.05*0.85) -> 2052.75 | J37: =IF(D37="","",I37*G37) -> 0 | L37: =IF(G37="","",K37*G37) -> 0 | M37: =IF(D37="","",_xlfn.XLOOKUP(A37,'3'!A:A,'3'!D:D,IF($M$6=0,0,"ERROR"))) -> 0 | N37: =IF(G37="","",M37*G37) -> 0 | O37: =IF(D37="","",_xlfn.XLOOKUP(A37,'4'!A:A,'4'!D:D,IF($O$6=0,0,"ERROR"))) -> 0 | P37: =IF(G37="","",O37*G37) -> 0 | Q37: =IF(D37="","",_xlfn.XLOOKUP(A37,'5'!A:A,'5'!D:D,IF($Q$6=0,0,"ERROR"))) -> 0 | R37: =IF(G37="","",Q37*G37) -> 0 | S37: =IF(D37="","",_xlfn.XLOOKUP(A37,'6'!A:A,'6'!D:D,IF($Q$6=0,0,"ERROR"))) -> 0 | T37: =IF(G37="","",S37*G37) -> 0 | U37: =IF(D37="","",_xlfn.XLOOKUP(A37,'7'!A:A,'7'!D:D,IF($U$6=0,0,"ERROR"))) -> 1.5 | V37: =IF(G37="","",U37*G37) -> 3079.125 | W37: =IF(D37="","",_xlfn.XLOOKUP(A37,'8'!A:A,'8'!D:D,IF($U$6=0,0,"ERROR"))) -> 0 | X37: =IF(G37="","",W37*G37) -> 0 | Y37: =IF(D37="","",_xlfn.XLOOKUP(A37,'9'!A:A,'9'!D:D,IF($U$6=0,0,"ERROR"))) -> 0 | Z37: =IF(G37="","",Y37*G37) -> 0 | AA37: =IF(D37="","",_xlfn.XLOOKUP(A37,'10'!A:A,'10'!D:D,IF($U$6=0,0,"ERROR"))) -> 0 | AB37: =IF(G37="","",AA37*G37) -> 0 | AC37: =IF(D37="","",_xlfn.XLOOKUP(A37,'11'!A:A,'11'!D:D,IF($U$6=0,0,"ERROR"))) -> 0 | AD37: =IF(G37="","",AC37*G37) -> 0 | AE37: =IF(D37="","",_xlfn.XLOOKUP(A37,'12'!A:A,'12'!D:D,IF($U$6=0,0,"ERROR"))) -> 0 | AF37: =IF(G37="","",AE37*G37) -> 0 | AG37: =IF(D37="","",_xlfn.XLOOKUP(A37,'13'!A:A,'13'!D:D,IF($U$6=0,0,"ERROR"))) -> 0 | AH37: =IF(G37="","",AG37*G37) -> 0 | AI37: =IF(D37="","",_xlfn.XLOOKUP(A37,'14'!A:A,'14'!D:D,IF($U$6=0,0,"ERROR"))) -> 0 | AJ37: =IF(G37="","",AI37*G37) -> 0 | AM37: =IF(D37="","",Q37+O37+M37+K37+I37+S37+U37+W37+Y37+AA37+AC37+AE37+AG37+AI37) -> 1.5 | AN37: =IF(D37="","",R37+P37+N37+L37+J37+T37+V37+X37+Z37+AB37+AD37+AH37+AF37+AJ37) -> 3079.125 | AO37: =IF(AN37="","",IF(AM37*G37=AN37,"הכל טוב","לא טוב")) -> הכל טוב
A38: 12.053.0450 | B38: דלת ציר שני אגפים מאולגנת/צבועה כדוגמת קליל קלאסי 4500 או ש"ע, זכוכית מחוסמת בעובי 6 מ"מ, בשטח מעל 3.0 מ"ר ועד 4.0 מ"ר | C38: מ"ר | D38: 3250 | E38: =IF(D38="","",D38*0.15) -> 487.5 | F38: =IF(D38="","",D38*0.05) -> 162.5 | G38: =IF(D38="","",D38*1.05*0.85) -> 2900.625 | J38: =IF(D38="","",I38*G38) -> 0 | L38: =IF(G38="","",K38*G38) -> 0 | M38: =IF(D38="","",_xlfn.XLOOKUP(A38,'3'!A:A,'3'!D:D,IF($M$6=0,0,"ERROR"))) -> 0 | N38: =IF(G38="","",M38*G38) -> 0 | O38: =IF(D38="","",_xlfn.XLOOKUP(A38,'4'!A:A,'4'!D:D,IF($O$6=0,0,"ERROR"))) -> 0 | P38: =IF(G38="","",O38*G38) -> 0 | Q38: =IF(D38="","",_xlfn.XLOOKUP(A38,'5'!A:A,'5'!D:D,IF($Q$6=0,0,"ERROR"))) -> 0 | R38: =IF(G38="","",Q38*G38) -> 0 | S38: =IF(D38="","",_xlfn.XLOOKUP(A38,'6'!A:A,'6'!D:D,IF($Q$6=0,0,"ERROR"))) -> 0 | T38: =IF(G38="","",S38*G38) -> 0 | U38: =IF(D38="","",_xlfn.XLOOKUP(A38,'7'!A:A,'7'!D:D,IF($U$6=0,0,"ERROR"))) -> 0 | V38: =IF(G38="","",U38*G38) -> 0 | W38: =IF(D38="","",_xlfn.XLOOKUP(A38,'8'!A:A,'8'!D:D,IF($U$6=0,0,"ERROR"))) -> 0 | X38: =IF(G38="","",W38*G38) -> 0 | Y38: =IF(D38="","",_xlfn.XLOOKUP(A38,'9'!A:A,'9'!D:D,IF($U$6=0,0,"ERROR"))) -> 0 | Z38: =IF(G38="","",Y38*G38) -> 0 | AA38: =IF(D38="","",_xlfn.XLOOKUP(A38,'10'!A:A,'10'!D:D,IF($U$6=0,0,"ERROR"))) -> 0 | AB38: =IF(G38="","",AA38*G38) -> 0 | AC38: =IF(D38="","",_xlfn.XLOOKUP(A38,'11'!A:A,'11'!D:D,IF($U$6=0,0,"ERROR"))) -> 0 | AD38: =IF(G38="","",AC38*G38) -> 0 | AE38: =IF(D38="","",_xlfn.XLOOKUP(A38,'12'!A:A,'12'!D:D,IF($U$6=0,0,"ERROR"))) -> 0 | AF38: =IF(G38="","",AE38*G38) -> 0 | AG38: =IF(D38="","",_xlfn.XLOOKUP(A38,'13'!A:A,'13'!D:D,IF($U$6=0,0,"ERROR"))) -> 0 | AH38: =IF(G38="","",AG38*G38) -> 0 | AI38: =IF(D38="","",_xlfn.XLOOKUP(A38,'14'!A:A,'14'!D:D,IF($U$6=0,0,"ERROR"))) -> 0 | AJ38: =IF(G38="","",AI38*G38) -> 0 | AM38: =IF(D38="","",Q38+O38+M38+K38+I38+S38+U38+W38+Y38+AA38+AC38+AE38+AG38+AI38) -> 0 | AN38: =IF(D38="","",R38+P38+N38+L38+J38+T38+V38+X38+Z38+AB38+AD38+AH38+AF38+AJ38) -> 0 | AO38: =IF(AN38="","",IF(AM38*G38=AN38,"הכל טוב","לא טוב")) -> הכל טוב
