Workbook

Sheet גיליון1
C1: רחמנפר | D1: 1776 | K1: נתוני מדידה גולמיים (קלט מריכוז כמויות)
K2: שדה | L2: ערך
K3: מס' חדרים | L3: 4
K4: היקף כולל | L4: 46.14
K5: שטח ויטרינה | L5: 13.5432
A6: סעיף | B6: תאור | C6: יח' | D6: כמות | E6: מחיר | F6: הנחת קבלן 15% | G6: תוספת דירה מאוכלסת 5% | H6: סה"כ מחיר יחידה | I6: סה"כ אחרי הנחה | K6: שטח קיפ+קבוע | L6: 3.9525
A7: 60.020.0090 | B7: חשמלאי מוסמך | C7: ש"ע | D7: =IF(SUM(D46,D47,D48,D49,D50,D51)>0,2,0) -> 2 | E7: 150 | F7: =IF(E7="","",E7*0.15) -> 22.5 | G7: =IF(E7="","",E7*0.05) -> 7.5 | H7: =IF(E7="","",E7*1.05*0.85) -> 133.875 | I7: =IF(D7="","",H7*D7) -> 267.75 | K7: שטח רשת כולל | L7: 2.408
A8: 09 | B8: עבודות טיח | K8: מס' חלונות עד 2 מ"ר | L8: 3
A9: 09.011 | B9: טיח פנים | K9: מס' חלונות מעל 2 מ"ר ועד 3 מ"ר | L9: 2
A10: 09.011.9030 | B10: תיקוני טיח פנים קיים על שטחים מישוריים ברצועות רוחב מעל 15 ס"מ ועד 30 ס"מ לאחר הנחת קווי מים, חשמל וכד' בקירות, סביב משקופי חלונות ודלתות שהורכבו בקירות קיימים, במפגשים בין קירות ו/או תקרות חדשים לקיימים הכל לרבות סיתות והתאמת עובי הטיח החדש לקיים | C10: מ' | D10: =L4 -> 46.14 | E10: 64 | F10: =IF(E10="","",E10*0.15) -> 9.6 | G10: =IF(E10="","",E10*0.05) -> 3.2 | H10: =IF(E10="","",E10*1.05*0.85) -> 57.12 | I10: =IF(D10="","",H10*D10) -> 2635.5168 | K10: מספר חלונות מעל 3 מ"ר ועד 5 מ"ר | L10: 0
A11: 11 | B11: עבודות צביעה | K11: רוחב 0-100 | L11: 3
A12: 11.011 | B12: צבע וסיוד פנים, על טיח, בטון, בלוקים וגבס | K12: רוחב 101-150 | L12: 2
A13: 11.011.9660 | B13: חידוש צבע פנים על קירות בדירת חדר מרוהטת בשטח 25-35 מ"ר ובגובה עד 2.70 מ'. הקירות ייצבעו בצבע אקרילי, ללא צביעת התקרות, לרבות הסרת צבע רופף, תיקונים קלים וסתימת חורים, ליטוש הקיר וניקוי שאריות הצבע בגמר העבודה | C13: קומפ | D13: =L3 -> 4 | E13: 1770 | F13: =IF(E13="","",E13*0.15) -> 265.5 | G13: =IF(E13="","",E13*0.05) -> 88.5 | H13: =IF(E13="","",E13*1.05*0.85) -> 1579.725 | I13: =IF(D13="","",H13*D13) -> 6318.9 | K13: רוחב 151-200 | L13: 0
K14: רוחב 201-250 | L14: 1
A15: 12 | B15: עבודות אלומיניום | K15: רוחב 251-300 | L15: 0
A16: 12.011 | B16: חלון אלומיניום נגרר אגף על אגף (הזזה) של 2 ו-3 אגפים | K16: רוחב 301-350 | L16: 0
A17: 12.011.0210 | B17: חלון נגרר אגף על אגף של 2 אגפים ב-2 מסלולים מאולגן/צבוע כדוגמת קליל קלאסי 7000 או ש"ע, זכוכית שקופה בידודית 5+6+6 מ"מ, בשטח מעל 1.0 מ"ר ועד 2.0 מ"ר | C17: מ"ר | D17: 0 | E17: 1760 | F17: =IF(E17="","",E17*0.15) -> 264 | G17: =IF(E17="","",E17*0.05) -> 88 | H17: =IF(E17="","",E17*1.05*0.85) -> 1570.8 | I17: =IF(D17="","",H17*D17) -> 0 | K17: רוחב 351-400 | L17: 1
A18: 12.011.0270 | B18: חלון נגרר אגף על אגף של 2 אגפים ב-2 מסלולים מאולגן/צבוע כדוגמת קליל קלאסי 9000 או ש"ע, זכוכית שקופה בידודית 5+6+6 מ"מ, בשטח מעל 2.0 מ"ר ועד 3.0 מ"ר | C18: מ"ר | D18: =L32+L33 -> 4.816 | E18: 1980 | F18: =IF(E18="","",E18*0.15) -> 297 | G18: =IF(E18="","",E18*0.05) -> 99 | H18: =IF(E18="","",E18*1.05*0.85) -> 1767.15 | I18: =IF(D18="","",H18*D18) -> 8510.5944 | K18: רוחב 401-450 | L18: 0
A19: 12.012.0100 | B19: חלון נגרר אגף על אגף של 3 אגפים ב-3 מסלולים מאולגן/צבוע כדוגמת קליל קלאסי 9000 או ש"ע, זכוכית שקופה בידודית 5+6+6 מ"מ, בשטח מעל 1.0 מ"ר ועד 2.0 מ"ר | C19: מ"ר | D19: 0 | E19: 2210 | F19: =IF(E19="","",E19*0.15) -> 331.5 | G19: =IF(E19="","",E19*0.05) -> 110.5 | H19: =IF(E19="","",E19*1.05*0.85) -> 1972.425 | I19: =IF(D19="","",H19*D19) -> 0 | K19: קומה 0-3 | L19: 0
A20: 12.011.1001 | B20: תוספת עבור חלק קבוע בחלון נגרר אגף על אגף של 2 אגפים. התוספת הינה 15% למחיר מ"ר של החלון | C20: קומפ | D20: =L33*E18+L6*E27 -> 20207.43 | E20: 0.15 | F20: =IF(E20="","",E20*0.15) -> 0.0225 | G20: =IF(E20="","",E20*0.05) -> 0.0075 | H20: =IF(E20="","",E20*1.05*0.85) -> 0.133875 | I20: =IF(D20="","",H20*D20) -> 2705.2697 | K20: קומה 4-7 | L20: 1
A21: 12.011.9000 | B21: פירוק חלונות אלומיניום ומשקופיהם בשטח של עד 2 מ"ר | C21: יח' | D21: =L8 -> 3 | E21: 140 | F21: =IF(E21="","",E21*0.15) -> 21 | G21: =IF(E21="","",E21*0.05) -> 7 | H21: =IF(E21="","",E21*1.05*0.85) -> 124.95 | I21: =IF(D21="","",H21*D21) -> 374.85 | K21: קומה 7 ומעלה | L21: 0
A22: 12.011.9016 | B22: פירוק חלונות אלומיניום ומשקופיהם בשטח של מעל 2 מ"ר ועד 3 מ"ר | C22: יח' | D22: =L9 -> 2 | E22: 240 | F22: =IF(E22="","",E22*0.15) -> 36 | G22: =IF(E22="","",E22*0.05) -> 12 | H22: =IF(E22="","",E22*1.05*0.85) -> 214.2 | I22: =IF(D22="","",H22*D22) -> 428.4 | K22: שטח תריסים לחלונות (אור) | L22: 10.3735
A23: 12.011.9017 | B23: פירוק חלונות אלומיניום ומשקופיהם בשטח של מעל 3 מ"ר ועד 5 מ"ר | C23: יח' | D23: =L10 -> 0 | E23: 310 | F23: =IF(E23="","",E23*0.15) -> 46.5 | G23: =IF(E23="","",E23*0.05) -> 15.5 | H23: =IF(E23="","",E23*1.05*0.85) -> 276.675 | I23: =IF(D23="","",H23*D23) -> 0 | K23: שטח תריסים לדלתות (אור) | L23: 15.3252
A24: 12.014 | B24: חלון אלומיניום ציר צד וחלון דו-צירי סב-נטוי | K24: כמות מנוע עד 20 | L24: 0
A25: 12.014.0400 | B25: חלון ציר-צד מאולגן/צבוע כדוגמת קליל קלאסי | C25: מ"ר | D25: 0 | E25: 2220 | F25: =IF(E25="","",E25*0.15) -> 333 | G25: =IF(E25="","",E25*0.05) -> 111 | H25: =IF(E25="","",E25*1.05*0.85) -> 1981.35 | I25: =IF(D25="","",H25*D25) -> 0 | K25: כמות מנוע 20–30 | L25: 0
A26: 12.014.0650 | B26: חלון ציר-צד מאולגן/צבוע כדוגמת קליל קלאסי | C26: מ"ר | D26: 0 | E26: 2790 | F26: =IF(E26="","",E26*0.15) -> 418.5 | G26: =IF(E26="","",E26*0.05) -> 139.5 | H26: =IF(E26="","",E26*1.05*0.85) -> 2490.075 | I26: =IF(D26="","",H26*D26) -> 0 | K26: כמות מנוע 30–50 | L26: 3
A27: 12.014.0660 | B27: חלון דו-צירי סב נטוי (דריי קיפ), מאולגן/צבוע | C27: מ"ר | D27: =L34+L6 -> 3.9525 | E27: 2700 | F27: =IF(E27="","",E27*0.15) -> 405 | G27: =IF(E27="","",E27*0.05) -> 135 | H27: =IF(E27="","",E27*1.05*0.85) -> 2409.75 | I27: =IF(D27="","",H27*D27) -> 9524.5369 | K27: כמות מנוע 50–70 | L27: 2
A28: 12.016 | B28: חלון אלומיניום קיפ וחלון קבוע | K28: כמות מנוע 70–90 | L28: 0
A29: 12.016.0600 | B29: חלון קבוע כדוגמת קליל קלאסי 4500 או ש"ע, בשטח מעל 0.6 מ"ר ועד 1.0 מ"ר | C29: יח' | D29: 0 | E29: 1310 | F29: =IF(E29="","",E29*0.15) -> 196.5 | G29: =IF(E29="","",E29*0.05) -> 65.5 | H29: =IF(E29="","",E29*1.05*0.85) -> 1169.175 | I29: =IF(D29="","",H29*D29) -> 0 | K29: כמות מנוע 90–120+ | L29: 2
A30: 12.016.0610 | B30: חלון קבוע כדוגמת קליל קלאסי 4500 או ש"ע, בשטח מעל 1.0 מ"ר ועד 2.0 מ"ר | C30: יח' | D30: 0 | E30: 2090 | F30: =IF(E30="","",E30*0.15) -> 313.5 | G30: =IF(E30="","",E30*0.05) -> 104.5 | H30: =IF(E30="","",E30*1.05*0.85) -> 1865.325 | I30: =IF(D30="","",H30*D30) -> 0 | K30: כמות טיפול בארגז | L30: 0
A31: 12.052 | B31: דלתות אלומיניום נגררות אגף על אגף (הזזה) של 3 אגפים | K31: סה"כ טקסאונד | L31: 3.387
A32: 12.052.0020 | B32: דלת נגררת אגף על אגף של 3 אגפים ב-3 מסלולים, קליל 7000, זכוכית מחוסמת 6 מ"מ, 6.0-8.0 מ"ר | C32: מ"ר | D32: 0 | E32: 1760 | F32: =IF(E32="","",E32*0.15) -> 264 | G32: =IF(E32="","",E32*0.05) -> 88 | H32: =IF(E32="","",E32*1.05*0.85) -> 1570.8 | I32: =IF(D32="","",H32*D32) -> 0 | K32: שטח הזזה | L32: 0
A33: 12.052.0070 | B33: דלת נגררת אגף על אגף של 3 אגפים ב-3 מסלולים, קליל 9000, זכוכית מחוסמת 6 מ"מ, 6.0-8.0 מ"ר | C33: מ"ר | D33: =L5 -> 13.5432 | E33: 1850 | F33: =IF(E33="","",E33*0.15) -> 277.5 | G33: =IF(E33="","",E33*0.05) -> 92.5 | H33: =IF(E33="","",E33*1.05*0.85) -> 1651.125 | I33: =IF(D33="","",H33*D33) -> 22361.516 | K33: שטח הזזה+קבוע | L33: 4.816
A34: 12.052.0080 | B34: דלת נגררת אגף על אגף של 3 אגפים ב-3 מסלולים, קליל 9000, זכוכית מחוסמת 8 מ"מ, 8.0-10.0 מ"ר | C34: מ"ר | D34: 0 | E34: 1680 | F34: =IF(E34="","",E34*0.15) -> 252 | G34: =IF(E34="","",E34*0.05) -> 84 | H34: =IF(E34="","",E34*1.05*0.85) -> 1499.4 | I34: =IF(D34="","",H34*D34) -> 0 | K34: שטח קיפ | L34: 0
A35: 12.053 | B35: דלתות אלומיניום ציריות | K35: שטח חלון ציר | L35: 0
A36: 12.053.0200 | B36: דלת ציר אגף אחד, קליל 4500, זכוכית מחוסמת 6 מ"מ, עד 2.0 מ"ר | C36: מ"ר | D36: =L38 -> 0 | E36: 2850 | F36: =IF(E36="","",E36*0.15) -> 427.5 | G36: =IF(E36="","",E36*0.05) -> 142.5 | H36: =IF(E36="","",E36*1.05*0.85) -> 2543.625 | I36: =IF(D36="","",H36*D36) -> 0 | K36: שטח תריסים לחלונות | L36: 0
A37: 12.053.0210 | B37: דלת ציר אגף אחד, קליל 4500, זכוכית מחוסמת 6 מ"מ, 2.0-3.0 מ"ר | C37: מ"ר | D37: 0 | E37: 2300 | F37: =IF(E37="","",E37*0.15) -> 345 | G37: =IF(E37="","",E37*0.05) -> 115 | H37: =IF(E37="","",E37*1.05*0.85) -> 2052.75 | I37: =IF(D37="","",H37*D37) -> 0 | K37: שטח תריסים לדלתות | L37: 0
A38: 12.053.0450 | B38: דלת ציר שני אגפים, קליל קלאסי 4500, זכוכית מחוסמת 6 מ"מ, 3.0-4.0 מ"ר | C38: מ"ר | D38: 0 | E38: 3250 | F38: =IF(E38="","",E38*0.15) -> 487.5 | G38: =IF(E38="","",E38*0.05) -> 162.5 | H38: =IF(E38="","",E38*1.05*0.85) -> 2900.625 | I38: =IF(D38="","",H38*D38) -> 0 | K38: שטח דלת ציר | L38: 0
A39: 12.061 | B39: ויטרינות כניסה מאלומיניום בשטחים ציבוריים
A40: 12.061.9000 | B40: פירוק ויטרינה מאלומיניום, לרבות המשקוף | C40: מ"ר | D40: =D32+D33+D34+D36+D37+D38 -> 13.5432 | E40: 88 | F40: =IF(E40="","",E40*0.15) -> 13.2 | G40: =IF(E40="","",E40*0.05) -> 4.4 | H40: =IF(E40="","",E40*1.05*0.85) -> 78.54 | I40: =IF(D40="","",H40*D40) -> 1063.6829
...

Sheet גיליון2
A2: פירוט כמויות
A3: הזמנה מס' | B3: =גיליון1!D1 -> 1776 | D3: כתובת | E3: משה רינת 4, קומה 7 דירה 25
A7: תיאור המדידה | B7: כמות | C7: יח' מידה
A8: שטח חלונות הזזה | B8: =_xlfn.XLOOKUP(A11,גיליון1!A:A,גיליון1!D:D,"לא מוצא") -> 4.816 | C8: מ"ר
A9: מכיל את הסעיפים: | E9: אורך כפול רוחב החלון
A10: מס' סעיף | B10: תיאור סעיף
A11: 12.011.0270 | B11: חלון אגף על אגף
A12: 12.011.1001 | B12: תוספת עבור חלק קבוע
A13: 12.065.1613 | B13: תריס גלילה
A14: 12.093.0022 | B14: תוספת עבור צבע מטאלי
A16: תיאור המדידה | B16: כמות | C16: יח' מידה
A17: מטר אורך היקף חלונות וויטרינות | B17: =_xlfn.XLOOKUP(A20,גיליון1!A:A,גיליון1!D:D,"לא מוצא") -> 46.14 | C17: מטר
A18: מכיל את הסעיפים: | E18: פעמיים אורך החלון + פעמיים רוחב החלון אם מדובר בויטרינה - רוחב החלון נמדד רק פעם אחת
A19: מס' סעיף | B19: תיאור סעיף
A20: 09.011.9030 | B20: תיקוני טיח פנים על שטחים מישוריים
A23: תיאור המדידה | B23: כמות | C23: יח' מידה
A24: מס' חדרים | B24: =_xlfn.XLOOKUP(A27,גיליון1!A:A,גיליון1!D:D,"לא מוצא") -> 4 | C24: קומפ' | E24: מס' החדרים שבהם הוחלפו חלונות או ויטרינות סלון+מטבח נמדדים כחדר וחצי
A25: מכיל את הסעיפים:
A26: מס' סעיף | B26: תיאור סעיף
A27: 11.011.9660 | B27: חידוש צבע פנים לחדר כולל תיקונים
A30: תיאור המדידה | B30: כמות | C30: יח' מידה | E30: מס' החלונות שפורקו
A31: מס' חלונות | B31: =_xlfn.XLOOKUP(A34,גיליון1!A:A,גיליון1!D:D,"לא מוצא") -> 0 | C31: יח'
A32: מכיל את הסעיפים:
A33: מס' סעיף | B33: תיאור סעיף
A34: 12.011.9017 | B34: פירוק חלונות אלומיניום ומשקופיהם
A37: תיאור המדידה | B37: כמות | C37: יח' מידה | E37: אורך כפול רוחב הויטרינה
A38: שטח ויטרינות | B38: =_xlfn.XLOOKUP(A41,גיליון1!A:A,גיליון1!D:D,"לא מוצא") -> 13.5432 | C38: מ"ר
A39: מכיל את הסעיפים:
A40: מס' סעיף | B40: תיאור סעיף
A41: 12.052.0070 | B41: דלת נגררת אגף על אגף של 3 אגפים ב-3 מסלולים מאולגנת/צבועה כדוגמת קליל קלאסי 9000 או ש"ע, זכוכית מחוסמת בעובי 6 מ"מ, בשטח מעל 6.0 מ"ר ועד 8.0 מ"ר
A42: 12.061.9000 | B42: פירוק ויטרינה מאלומיניום, לרבות המשקוף
A43: 12.068.1216 | B43: זכוכית שקופה בידודית מחוסמת משני הצדדים 6+10+8 מ"מ
A44: 12.068.1004 | B44: הפחתת זכוכית שטוחה מחוסמת בעובי 6 מ"מ
A45: 12.065.1615 | B45: תריס גלילה עם רפפות מפח אלומיניום עם פוליאוריטן מוקצף לרבות ארגז תריס מונובלוק 40, בשטח מעל 3.0 מ"ר ועד 6.0 מ"ר
A46: 12.093.0022 | B46: תוספת עבור צבע מטאלי
A48: תיאור המדידה | B48: כמות | C48: יח' מידה | E48: כמות המנועים שהוחלפו פירוט הכמות נמצא בכתב הכמויות כדי לא להעמיס על המסמך
A49: מנועים חשמליים | B49: =SUM(D52:D57) -> 7 | C49: יח'
A50: מכיל את הסעיפים:
A51: מס' סעיף | B51: תיאור סעיף | D51: כמות
A52: 12.065.2000 | B52: מנוע חשמלי לתריס במשקל עד 20 ק"ג, לא כולל נק' החשמל | C52: מנוע חשמלי לתריס במשקל עד 20 ק"ג, לא כולל נק' החשמל | D52: =_xlfn.XLOOKUP(A52,גיליון1!A:A,גיליון1!D:D,0) -> 0
...
