Workbook

Sheet ריכוז
A1: חשבון מרוכז
H3: כהן אלדן | I3: 1549
A4: סעיף | B4: תאור | C4: יח' | D4: מחיר | E4: הנחת קבלן 15% | F4: תוספת דירה מאוכלסת 5% | G4: סה"כ מחיר יחידה | H4: כמות | I4: סה"כ לדירה | J4: סה"כ כמות חשבון | K4: סה"כ סכום חשבון
A7: 60.020.0090 | B7: חשמלאי מוסמך | C7: ש"ע | D7: 150 | E7: =IF(D7="","",D7*0.15) -> 22.5 | F7: =IF(D7="","",D7*0.05) -> 7.5 | G7: =IF(D7="","",D7*1.05*0.85) -> 133.875 | H7: ='1549'!D7 -> 4 | I7: =IF(H7="","",H7*G7) -> 535.5 | J7: =H7 -> 4 | K7: =I7 -> 535.5
A8: 09 | B8: עבודות טיח
A9: 09.011 | B9: טיח פנים
A10: 09.011.9030 | B10: תיקוני טיח פנים קיים על שטחים מישוריים ברצועות רוחב מעל 15 ס"מ ועד 30 ס"מ לאחר הנחת קווי מים, חשמל וכד' בקירות, סביב משקופי חלונות ודלתות שהורכבו בקירות קיימים, במפגשים בין קירות ו/או תקרות חדשים לקיימים הכל לרבות סיתות והתאמת עובי הטיח החדש לקיים | C10: מ' | D10: 64 | E10: =IF(D10="","",D10*0.15) -> 9.6 | F10: =IF(D10="","",D10*0.05) -> 3.2 | G10: =IF(D10="","",D10*1.05*0.85) -> 57.12 | H10: ='1549'!D10 -> 31.96 | I10: =IF(H10="","",H10*G10) -> 1825.5552 | J10: =H10 -> 31.96 | K10: =I10 -> 1825.5552
A11: 11 | B11: עבודות צביעה
A12: 11.011 | B12: צבע וסיוד פנים, על טיח, בטון, בלוקים וגבס
A13: 11.011.9660 | B13: חידוש צבע פנים על קירות בדירת חדר מרוהטת בשטח 25-35 מ"ר ובגובה עד 2.70 מ'. הקירות ייצבעו בצבע אקרילי, ללא צביעת התקרות, לרבות הסרת צבע רופף, תיקונים קלים וסתימת חורים, ליטוש הקיר וניקוי שאריות הצבע בגמר העבודה | C13: קומפ | D13: 1770 | E13: =IF(D13="","",D13*0.15) -> 265.5 | F13: =IF(D13="","",D13*0.05) -> 88.5 | G13: =IF(D13="","",D13*1.05*0.85) -> 1579.725 | H13: ='1549'!D13 -> 4 | I13: =IF(H13="","",H13*G13) -> 6318.9 | J13: =H13 -> 4 | K13: =I13 -> 6318.9
A15: 12 | B15: עבודות אלומיניום
A16: 12.011 | B16: חלון אלומיניום נגרר אגף על אגף (הזזה) של 2 אגפים ב-2 מסלולים
A17: 12.011.0210 | B17: חלון נגרר אגף על אגף של 2 אגפים ב-2 מסלולים מאולגן/צבוע כדוגמת קליל קלאסי 7000 או ש"ע, זכוכית שקופה בידודית 5+6+6 מ"מ, בשטח מעל 1.0 מ"ר ועד 2.0 מ"ר | C17: מ"ר | D17: 1760 | E17: =IF(D17="","",D17*0.15) -> 264 | F17: =IF(D17="","",D17*0.05) -> 88 | G17: =IF(D17="","",D17*1.05*0.85) -> 1570.8 | H17: ='1549'!D17 -> 0 | I17: =IF(H17="","",H17*G17) -> 0 | J17: =H17 -> 0 | K17: =I17 -> 0
A18: 12.011.0260 | B18: חלון נגרר אגף על אגף של 2 אגפים ב-2 מסלולים מאולגן/צבוע כדוגמת קליל קלאסי 9000 או ש"ע, זכוכית שקופה בידודית 5+6+6 מ"מ, בשטח מעל 0.6 מ"ר ועד 1.0 מ"ר | C18: מ"ר | D18: 2440 | E18: =IF(D18="","",D18*0.15) -> 366 | F18: =IF(D18="","",D18*0.05) -> 122 | G18: =IF(D18="","",D18*1.05*0.85) -> 2177.7 | H18: ='1549'!D18 -> 0 | I18: =IF(H18="","",H18*G18) -> 0 | J18: =H18 -> 0 | K18: =I18 -> 0
A19: 12.011.0265 | B19: חלון נגרר אגף על אגף של 2 אגפים ב-2 מסלולים מאולגן/צבוע כדוגמת קליל קלאסי 9000 או ש"ע, זכוכית שקופה בידודית 5+6+6 מ"מ, בשטח מעל 1.0 מ"ר ועד 2.0 מ"ר | C19: מ"ר | D19: 2120 | E19: =IF(D19="","",D19*0.15) -> 318 | F19: =IF(D19="","",D19*0.05) -> 106 | G19: =IF(D19="","",D19*1.05*0.85) -> 1892.1 | H19: ='1549'!D19 -> 0 | I19: =IF(H19="","",H19*G19) -> 0 | J19: =H19 -> 0 | K19: =I19 -> 0
A20: 12.011.0270 | B20: חלון נגרר אגף על אגף של 2 אגפים ב-2 מסלולים מאולגן/צבוע כדוגמת קליל קלאסי 9000 או ש"ע, זכוכית שקופה בידודית מחוסמת דו צדדי 6+10+8 מ"מ, בשטח מעל 2.0 מ"ר ועד 3.0 מ"ר | C20: מ"ר | D20: 1980 | E20: =IF(D20="","",D20*0.15) -> 297 | F20: =IF(D20="","",D20*0.05) -> 99 | G20: =IF(D20="","",D20*1.05*0.85) -> 1767.15 | H20: ='1549'!D20 -> 0 | I20: =IF(H20="","",H20*G20) -> 0 | J20: =H20 -> 0 | K20: =I20 -> 0
A21: 12.011.0275 | B21: חלון נגרר אגף על אגף של 2 אגפים ב-2 מסלולים מאולגן/צבוע כדוגמת קליל קלאסי 9000 או ש"ע, זכוכית שקופה בידודית מחוסמת דו צדדי 6+10+8 מ"מ, בשטח מעל 3.0 מ"ר ועד 4.0 מ"ר | C21: מ"ר | D21: 1760 | E21: =IF(D21="","",D21*0.15) -> 264 | F21: =IF(D21="","",D21*0.05) -> 88 | G21: =IF(D21="","",D21*1.05*0.85) -> 1570.8 | H21: ='1549'!D21 -> 11.115 | I21: =IF(H21="","",H21*G21) -> 17459.442 | J21: =H21 -> 11.115 | K21: =I21 -> 17459.442
A22: 12.011.0280 | B22: חלון נגרר אגף על אגף של 2 אגפים ב-2 מסלולים מאולגן/צבוע כדוגמת קליל קלאסי 9000 או ש"ע, זכוכית שקופה בידודית מחוסמת דו צדדי 6+10+10 מ"מ, בשטח מעל 4.0 מ"ר ועד 5.0 מ"ר | C22: מ"ר | D22: 1630 | E22: =IF(D22="","",D22*0.15) -> 244.5 | F22: =IF(D22="","",D22*0.05) -> 81.5 | G22: =IF(D22="","",D22*1.05*0.85) -> 1454.775 | H22: ='1549'!D22 -> 0 | I22: =IF(H22="","",H22*G22) -> 0 | J22: =H22 -> 0 | K22: =I22 -> 0
A23: 12.011.0285 | B23: חלון נגרר אגף על אגף של 2 אגפים ב-2 מסלולים מאולגן/צבוע כדוגמת קליל קלאסי 9000 או ש"ע, זכוכית שקופה בידודית מחוסמת דו צדדי 6+10+8 מ"מ, בשטח מעל 5.0 מ"ר ועד 6.0 מ"ר | C23: מ"ר | D23: 1490 | E23: =IF(D23="","",D23*0.15) -> 223.5 | F23: =IF(D23="","",D23*0.05) -> 74.5 | G23: =IF(D23="","",D23*1.05*0.85) -> 1329.825 | H23: ='1549'!D23 -> 0 | I23: =IF(H23="","",H23*G23) -> 0 | J23: =H23 -> 0 | K23: =I23 -> 0
A24: 12.012.0100 | B24: חלון נגרר אגף על אגף של 3 אגפים ב-3 מסלולים מאולגן/צבוע כדוגמת קליל קלאסי 9000 או ש"ע, זכוכית שקופה בידודית 5+6+6 מ"מ, בשטח מעל 1.0 מ"ר ועד 2.0 מ"ר | C24: מ"ר | D24: 2210 | E24: =IF(D24="","",D24*0.15) -> 331.5 | F24: =IF(D24="","",D24*0.05) -> 110.5 | G24: =IF(D24="","",D24*1.05*0.85) -> 1972.425 | H24: ='1549'!D24 -> 0 | I24: =IF(H24="","",H24*G24) -> 0 | J24: =H24 -> 0 | K24: =I24 -> 0
A25: 12.012.0110 | B25: חלון נגרר אגף על אגף של 3 אגפים ב-3 מסלולים מאולגן/צבוע כדוגמת קליל קלאסי 9000 או ש"ע, זכוכית שקופה בידודית 5+6+6 מ"מ, בשטח מעל 2.0 מ"ר ועד 3.0 מ"ר | C25: מ"ר | D25: 2110 | E25: =IF(D25="","",D25*0.15) -> 316.5 | F25: =IF(D25="","",D25*0.05) -> 105.5 | G25: =IF(D25="","",D25*1.05*0.85) -> 1883.175 | H25: ='1549'!D25 -> 0 | I25: =IF(H25="","",H25*G25) -> 0 | J25: =H25 -> 0 | K25: =I25 -> 0
A26: 12.012.0120 | B26: חלון נגרר אגף על אגף של 3 אגפים ב-3 מסלולים מאולגן/צבוע כדוגמת קליל קלאסי 9000 או ש"ע, זכוכית שקופה בידודית מחוסמת דו צדדי 6+10+8 מ"מ, בשטח מעל 3.0 מ"ר ועד 5.0 מ"ר | C26: מ"ר | D26: 2060 | E26: =IF(D26="","",D26*0.15) -> 309 | F26: =IF(D26="","",D26*0.05) -> 103 | G26: =IF(D26="","",D26*1.05*0.85) -> 1838.55 | H26: ='1549'!D26 -> 0 | I26: =IF(H26="","",H26*G26) -> 0 | J26: =H26 -> 0 | K26: =I26 -> 0
A27: 12.012.0130 | B27: חלון נגרר אגף על אגף של 3 אגפים ב-3 מסלולים מאולגן/צבוע כדוגמת קליל קלאסי 9000 או ש"ע, זכוכית שקופה בידודית מחוסמת דו צדדי 6+10+8 מ"מ, בשטח מעל 5.0 מ"ר ועד 7.0 מ"ר | C27: מ"ר | D27: 1970 | E27: =IF(D27="","",D27*0.15) -> 295.5 | F27: =IF(D27="","",D27*0.05) -> 98.5 | G27: =IF(D27="","",D27*1.05*0.85) -> 1758.225 | H27: ='1549'!D27 -> 0 | I27: =IF(H27="","",H27*G27) -> 0 | J27: =H27 -> 0 | K27: =I27 -> 0
A28: 12.012.0560 | B28: חלון נגרר אגף על אגף של 4 אגפים ב-2 מסלולים מאולגן/צבוע כדוגמת קליל קלאסי 9000 או ש"ע, זכוכית שקופה בידודית 6+10+8 מ"מ, בשטח מעל 3.0 מ"ר ועד 5.0 מ"ר | C28: מ"ר | D28: 2300 | E28: =IF(D28="","",D28*0.15) -> 345 | F28: =IF(D28="","",D28*0.05) -> 115 | G28: =IF(D28="","",D28*1.05*0.85) -> 2052.75 | H28: ='1549'!D28 -> 0 | I28: =IF(H28="","",H28*G28) -> 0 | J28: =H28 -> 0 | K28: =I28 -> 0
... A32: 12.011.9017 | B32: פירוק חלונות אלומיניום ומשקופיהם בשטח של מעל 3 מ"ר ועד 5 מ"ר | C32: יח' | D32: 310 | E32: =IF(D32="","",D32*0.15) -> 46.5 | F32: =IF(D32="","",D32*0.05) -> 15.5 | G32: =IF(D32="","",D32*1.05*0.85) -> 276.675 | H32: ='1549'!D32 -> 3 | I32: =IF(H32="","",H32*G32) -> 830.025 | J32: =H32 -> 3 | K32: =I32 -> 830.025
A33: 12.014 | B33: חלון אלומיניום ציר צד וחלון דו-צירי סב-נטוי (DREH-KIPP)
A34: 12.014.0400 | B34: חלון ציר-צד מאולגן/צבוע כדוגמת קליל קלאסי 4500 או ש"ע, זכוכית שקופה בידודית 5+6+6 מ"מ, בשטח מעל 0.6 מ"ר ועד 1.0 מ"ר | C34: מ"ר | D34: 2220 | E34: =IF(D34="","",D34*0.15) -> 333 | F34: =IF(D34="","",D34*0.05) -> 111 | G34: =IF(D34="","",D34*1.05*0.85) -> 1981.35 | H34: ='1549'!D34 -> 0 | I34: =IF(H34="","",H34*G34) -> 0 | J34: =H34 -> 0 | K34: =I34 -> 0
A35: 12.014.0650 | B35: חלון ציר-צד מאולגן/צבוע כדוגמת קליל קלאסי 4500 או ש"ע, זכוכית שקופה בידודית 5+6+6 מ"מ, בשטח מעל 0.6 מ"ר ועד 1.0 מ"ר | C35: מ"ר | D35: 2790 | E35: =IF(D35="","",D35*0.15) -> 418.5 | F35: =IF(D35="","",D35*0.05) -> 139.5 | G35: =IF(D35="","",D35*1.05*0.85) -> 2490.075 | H35: ='1549'!D35 -> 0 | I35: =IF(H35="","",H35*G35) -> 0 | J35: =H35 -> 0 | K35: =I35 -> 0
A36: 12.014.0660 | B36: חלון דו-צירי סב נטוי (דריי קיפ), מאולגן/צבוע כדוגמת קליל קלאסי 4500 או ש"ע, זכוכית שקופה בידודית מחוסמת דו צדדי 6+10+8 מ"מ, בשטח מעל 1.0 מ"ר ועד 2.0 מ"ר | C36: מ"ר | D36: 2700 | E36: =IF(D36="","",D36*0.15) -> 405 | F36: =IF(D36="","",D36*0.05) -> 135 | G36: =IF(D36="","",D36*1.05*0.85) -> 2409.75 | H36: ='1549'!D36 -> 0 | I36: =IF(H36="","",H36*G36) -> 0 | J36: =H36 -> 0 | K36: =I36 -> 0
A37: 12.016 | B37: חלון אלומיניום קיפ וחלון קבוע
A38: 12.016.0600 | B38: חלון קבוע כדוגמת קליל קלאסי 4500 או ש"ע, זכוכית שקופה בידודית 5+6+6 מ"מ, בשטח מעל 0.6 מ"ר ועד 1.0 מ"ר | C38: יח' | D38: 1310 | E38: =IF(D38="","",D38*0.15) -> 196.5 | F38: =IF(D38="","",D38*0.05) -> 65.5 | G38: =IF(D38="","",D38*1.05*0.85) -> 1169.175 | H38: ='1549'!D38 -> 0 | I38: =IF(H38="","",H38*G38) -> 0 | J38: =H38 -> 0 | K38: =I38 -> 0
A39: 12.016.0610 | B39: חלון קבוע כדוגמת קליל קלאסי 4500 או ש"ע, זכוכית שקופה בידודית 5+6+6 מ"מ, בשטח מעל 1.0 מ"ר ועד 2.0 מ"ר | C39: יח' | D39: 2090 | E39: =IF(D39="","",D39*0.15) -> 313.5 | F39: =IF(D39="","",D39*0.05) -> 104.5 | G39: =IF(D39="","",D39*1.05*0.85) -> 1865.325 | H39: ='1549'!D39 -> 0 | I39: =IF(H39="","",H39*G39) -> 0 | J39: =H39 -> 0 | K39: =I39 -> 0
A40: 12.051 | B40: דלתות/ויטרינות אלומיניום נגררות אגף על אגף (הזזה) של 2 אגפים
A41: 12.051.0460 | B41: דלת נגררת אגף על אגף של 2 אגפים ב-2 מסלולים מאולגנת/צבועה כדוגמת קליל קלאסי 9000 או ש"ע, זכוכית מחוסמת בעובי 8 מ"מ, בשטח מעל 4.0 מ"ר ועד 6.0 מ"ר | C41: מ"ר | D41: 1630 | E41: =IF(D41="","",D41*0.15) -> 244.5 | F41: =IF(D41="","",D41*0.05) -> 81.5 | G41: =IF(D41="","",D41*1.05*0.85) -> 1454.775 | H41: ='1549'!D41 -> 0 | I41: =IF(H41="","",H41*G41) -> 0 | J41: =H41 -> 0 | K41: =I41 -> 0
A42: 12.051.0470 | B42: דלת נגררת אגף על אגף של 2 אגפים ב-2 מסלולים מאולגנת/צבועה כדוגמת קליל קלאסי 9000 או ש"ע, זכוכית מחוסמת בעובי 8 מ"מ, בשטח מעל 6.0 מ"ר ועד 8.0 מ"ר | C42: מ"ר | D42: 1580 | E42: =IF(D42="","",D42*0.15) -> 237 | F42: =IF(D42="","",D42*0.05) -> 79 | G42: =IF(D42="","",D42*1.05*0.85) -> 1410.15 | H42: ='1549'!D42 -> 0 | I42: =IF(H42="","",H42*G42) -> 0 | J42: =H42 -> 0 | K42: =I42 -> 0
A43: 12.052 | B43: דלתות אלומיניום נגררות אגף על אגף (הזזה) של 3 אגפים ו-4 אגפים
A44: 12.052.0020 | B44: דלת נגררת אגף על אגף של 3 אגפים ב-3 מסלולים מאולגנת/צבועה כדוגמת קליל קלאסי 7000 או ש"ע, זכוכית מחוסמת בעובי 6 מ"מ, בשטח מעל 6.0 מ"ר ועד 8.0 מ"ר | C44: מ"ר | D44: 1760 | E44: =IF(D44="","",D44*0.15) -> 264 | F44: =IF(D44="","",D44*0.05) -> 88 | G44: =IF(D44="","",D44*1.05*0.85) -> 1570.8 | H44: ='1549'!D44 -> 0 | I44: =IF(H44="","",H44*G44) -> 0 | J44: =H44 -> 0 | K44: =I44 -> 0
A45: 12.052.0070 | B45: דלת נגררת אגף על אגף של 3 אגפים ב-3 מסלולים מאולגנת/צבועה כדוגמת קליל קלאסי 9000 או ש"ע, זכוכית מחוסמת בעובי 6 מ"מ, בשטח מעל 6.0 מ"ר ועד 8.0 מ"ר | C45: מ"ר | D45: 1850 | E45: =IF(D45="","",D45*0.15) -> 277.5 | F45: =IF(D45="","",D45*0.05) -> 92.5 | G45: =IF(D45="","",D45*1.05*0.85) -> 1651.125 | H45: ='1549'!D45 -> 7.85 | I45: =IF(H45="","",H45*G45) -> 12961.331 | J45: =H45 -> 7.85 | K45: =I45 -> 12961.331
A46: 12.052.0080 | B46: דלת נגררת אגף על אגף של 3 אגפים ב-3 מסלולים מאולגנת/צבועה כדוגמת קליל קלאסי 9000 או ש"ע, זכוכית מחוסמת בעובי 8 מ"מ, בשטח מעל 8.0 מ"ר ועד 10.0 מ"ר | C46: מ"ר | D46: 1680 | E46: =IF(D46="","",D46*0.15) -> 252 | F46: =IF(D46="","",D46*0.05) -> 84 | G46: =IF(D46="","",D46*1.05*0.85) -> 1499.4 | H46: ='1549'!D46 -> 0 | I46: =IF(H46="","",H46*G46) -> 0 | J46: =H46 -> 0 | K46: =I46 -> 0
A47: 12.052.0260 | B47: דלת נגררת אגף על אגף של 3 אגפים ב-3 מסלולים מאולגנת/צבועה כדוגמת קליל בלגי 7300 או ש"ע, זכוכית מחוסמת בעובי 6 מ"מ, בשטח מעל 6.0 מ"ר ועד 8.0 מ"ר | C47: מ"ר | D47: 2101 | E47: =IF(D47="","",D47*0.15) -> 315.15 | F47: =IF(D47="","",D47*0.05) -> 105.05 | G47: =IF(D47="","",D47*1.05*0.85) -> 1875.1425 | H47: ='1549'!D47 -> 0 | I47: =IF(H47="","",H47*G47) -> 0 | J47: =H47 -> 0 | K47: =I47 -> 0
...

Sheet רשימת כתובות
A1: מס' הזמנה | B1: שם משפחה | C1: כתובת | D1: קומה | E1: דירה
A2: 1549 | B2: כהן אלדן | C2: מנחם בגין 48 | D2: 5 | E2: 14

Sheet 1549
C1: כהן אלדן | D1: 1549 | K1: נתוני מדידה גולמיים (קלט מריכוז כמויות)
K2: שדה | L2: ערך
K3: מס' חדרים | L3: 4
K4: היקף כולל | L4: 31.96
K5: שטח ויטרינה | L5: 7.85
A6: סעיף | B6: תאור | C6: יח' | D6: כמות | E6: מחיר | F6: הנחת קבלן 15% | G6: תוספת דירה מאוכלסת 5% | H6: סה"כ מחיר יחידה | I6: סה"כ אחרי הנחה | K6: שטח קיפ+קבוע | L6: 0
A7: 60.020.0090 | B7: חשמלאי מוסמך | C7: ש"ע | D7: =IF(SUM(D65,D66,D67,D68,D69,D70)>0,2,0)+2 -> 4 | E7: 150 | F7: =IF(E7="","",E7*0.15) -> 22.5 | G7: =IF(E7="","",E7*0.05) -> 7.5 | H7: =IF(E7="","",E7*1.05*0.85) -> 133.875 | I7: =IF(D7="","",H7*D7) -> 535.5 | K7: שטח רשת כולל | L7: 10.817
A8: 09 | B8: עבודות טיח | K8: מס' חלונות עד 2 מ"ר | L8: 0
A9: 09.011 | B9: טיח פנים | K9: מס' חלונות מעל 2 מ"ר ועד 3 מ"ר | L9: 0
A10: 09.011.9030 | B10: תיקוני טיח פנים קיים על שטחים מישוריים ברצועות רוחב מעל 15 ס"מ ועד 30 ס"מ לאחר הנחת קווי מים, חשמל וכד' בקירות, סביב משקופי חלונות ודלתות שהורכבו בקירות קיימים, במפגשים בין קירות ו/או תקרות חדשים לקיימים הכל לרבות סיתות והתאמת עובי הטיח החדש לקיים | C10: מ' | D10: =L4 -> 31.96 | E10: 64 | F10: =IF(E10="","",E10*0.15) -> 9.6 | G10: =IF(E10="","",E10*0.05) -> 3.2 | H10: =IF(E10="","",E10*1.05*0.85) -> 57.12 | I10: =IF(D10="","",H10*D10) -> 1825.5552 | K10: מספר חלונות מעל 3 מ"ר ועד 5 מ"ר | L10: 3
A11: 11 | B11: עבודות צביעה | K11: רוחב 0-100 | L11: 0
A12: 11.011 | B12: צבע וסיוד פנים, על טיח, בטון, בלוקים וגבס | K12: רוחב 101-150 | L12: 3
A13: 11.011.9660 | B13: חידוש צבע פנים על קירות בדירת חדר מרוהטת בשטח 25-35 מ"ר ובגובה עד 2.70 מ'. הקירות ייצבעו בצבע אקרילי, ללא צביעת התקרות, לרבות הסרת צבע רופף, תיקונים קלים וסתימת חורים, ליטוש הקיר וניקוי שאריות הצבע בגמר העבודה | C13: קומפ | D13: =L3 -> 4 | E13: 1770 | F13: =IF(E13="","",E13*0.15) -> 265.5 | G13: =IF(E13="","",E13*0.05) -> 88.5 | H13: =IF(E13="","",E13*1.05*0.85) -> 1579.725 | I13: =IF(D13="","",H13*D13) -> 6318.9 | K13: רוחב 151-200 | L13: 0
K14: רוחב 201-250 | L14: 0
A15: 12 | B15: עבודות אלומיניום | K15: רוחב 251-300 | L15: 0
A16: 12.011 | B16: חלון אלומיניום נגרר אגף על אגף (הזזה) של 2 אגפים ב-2 מסלולים | K16: רוחב 301-350 | L16: 1
A17: 12.011.0210 | B17: חלון נגרר אגף על אגף של 2 אגפים ב-2 מסלולים מאולגן/צבוע כדוגמת קליל קלאסי 7000 או ש"ע, זכוכית שקופה בידודית 5+6+6 מ"מ, בשטח מעל 1.0 מ"ר ועד 2.0 מ"ר | C17: מ"ר | D17: 0 | E17: 1760 | F17: =IF(E17="","",E17*0.15) -> 264 | G17: =IF(E17="","",E17*0.05) -> 88 | H17: =IF(E17="","",E17*1.05*0.85) -> 1570.8 | I17: =IF(D17="","",H17*D17) -> 0 | K17: רוחב 351-400 | L17: 0
A18: 12.011.0260 | B18: חלון נגרר אגף על אגף של 2 אגפים ב-2 מסלולים מאולגן/צבוע כדוגמת קליל קלאסי 9000 או ש"ע, זכוכית שקופה בידודית 5+6+6 מ"מ, בשטח מעל 0.6 מ"ר ועד 1.0 מ"ר | C18: מ"ר | D18: 0 | E18: 2440 | F18: =IF(E18="","",E18*0.15) -> 366 | G18: =IF(E18="","",E18*0.05) -> 122 | H18: =IF(E18="","",E18*1.05*0.85) -> 2177.7 | I18: =IF(D18="","",H18*D18) -> 0 | K18: רוחב 401-450 | L18: 0
A19: 12.011.0265 | B19: חלון נגרר אגף על אגף של 2 אגפים ב-2 מסלולים מאולגן/צבוע כדוגמת קליל קלאסי 9000 או ש"ע, זכוכית שקופה בידודית 5+6+6 מ"מ, בשטח מעל 1.0 מ"ר ועד 2.0 מ"ר | C19: מ"ר | D19: 0 | E19: 2120 | F19: =IF(E19="","",E19*0.15) -> 318 | G19: =IF(E19="","",E19*0.05) -> 106 | H19: =IF(E19="","",E19*1.05*0.85) -> 1892.1 | I19: =IF(D19="","",H19*D19) -> 0 | K19: קומה 0-3 | L19: 0
A20: 12.011.0270 | B20: חלון נגרר אגף על אגף של 2 אגפים ב-2 מסלולים מאולגן/צבוע כדוגמת קליל קלאסי 9000 או ש"ע, זכוכית שקופה בידודית מחוסמת דו צדדי 6+10+8 מ"מ, בשטח מעל 2.0 מ"ר ועד 3.0 מ"ר | C20: מ"ר | D20: 0 | E20: 1980 | F20: =IF(E20="","",E20*0.15) -> 297 | G20: =IF(E20="","",E20*0.05) -> 99 | H20: =IF(E20="","",E20*1.05*0.85) -> 1767.15 | I20: =IF(D20="","",H20*D20) -> 0 | K20: קומה 4-7 | L20: 1
A21: 12.011.0275 | B21: חלון נגרר אגף על אגף של 2 אגפים ב-2 מסלולים מאולגן/צבוע כדוגמת קליל קלאסי 9000 או ש"ע, זכוכית שקופה בידודית מחוסמת דו צדדי 6+10+8 מ"מ, בשטח מעל 3.0 מ"ר ועד 4.0 מ"ר | C21: מ"ר | D21: 11.115 | E21: 1760 | F21: =IF(E21="","",E21*0.15) -> 264 | G21: =IF(E21="","",E21*0.05) -> 88 | H21: =IF(E21="","",E21*1.05*0.85) -> 1570.8 | I21: =IF(D21="","",H21*D21) -> 17459.442 | K21: קומה 7 ומעלה | L21: 0
A22: 12.011.0280 | B22: חלון נגרר אגף על אגף של 2 אגפים ב-2 מסלולים מאולגן/צבוע כדוגמת קליל קלאסי 9000 או ש"ע, זכוכית שקופה בידודית מחוסמת דו צדדי 6+10+10 מ"מ, בשטח מעל 4.0 מ"ר ועד 5.0 מ"ר | C22: מ"ר | D22: 0 | E22: 1630 | F22: =IF(E22="","",E22*0.15) -> 244.5 | G22: =IF(E22="","",E22*0.05) -> 81.5 | H22: =IF(E22="","",E22*1.05*0.85) -> 1454.775 | I22: =IF(D22="","",H22*D22) -> 0 | K22: שטח תריסים לחלונות (אור) | L22: 0
A23: 12.011.0285 | B23: חלון נגרר אגף על אגף של 2 אגפים ב-2 מסלולים מאולגן/צבוע כדוגמת קליל קלאסי 9000 או ש"ע, זכוכית שקופה בידודית מחוסמת דו צדדי 6+10+8 מ"מ, בשטח מעל 5.0 מ"ר ועד 6.0 מ"ר | C23: מ"ר | D23: 0 | E23: 1490 | F23: =IF(E23="","",E23*0.15) -> 223.5 | G23: =IF(E23="","",E23*0.05) -> 74.5 | H23: =IF(E23="","",E23*1.05*0.85) -> 1329.825 | I23: =IF(D23="","",H23*D23) -> 0 | K23: שטח תריסים לדלתות (אור) | L23: 0
A24: 12.012.0100 | B24: חלון נגרר אגף על אגף של 3 אגפים ב-3 מסלולים מאולגן/צבוע כדוגמת קליל קלאסי 9000 או ש"ע, זכוכית שקופה בידודית 5+6+6 מ"מ, בשטח מעל 1.0 מ"ר ועד 2.0 מ"ר | C24: מ"ר | D24: 0 | E24: 2210 | F24: =IF(E24="","",E24*0.15) -> 331.5 | G24: =IF(E24="","",E24*0.05) -> 110.5 | H24: =IF(E24="","",E24*1.05*0.85) -> 1972.425 | I24: =IF(D24="","",H24*D24) -> 0 | K24: כמות מנוע עד 20 | L24: 0
A25: 12.012.0110 | B25: חלון נגרר אגף על אגף של 3 אגפים ב-3 מסלולים מאולגן/צבוע כדוגמת קליל קלאסי 9000 או ש"ע, זכוכית שקופה בידודית 5+6+6 מ"מ, בשטח מעל 2.0 מ"ר ועד 3.0 מ"ר | C25: מ"ר | D25: 0 | E25: 2110 | F25: =IF(E25="","",E25*0.15) -> 316.5 | G25: =IF(E25="","",E25*0.05) -> 105.5 | H25: =IF(E25="","",E25*1.05*0.85) -> 1883.175 | I25: =IF(D25="","",H25*D25) -> 0 | K25: כמות מנוע 20–30 | L25: 0
A26: 12.012.0120 | B26: חלון נגרר אגף על אגף של 3 אגפים ב-3 מסלולים מאולגן/צבוע כדוגמת קליל קלאסי 9000 או ש"ע, זכוכית שקופה בידודית מחוסמת דו צדדי 6+10+8 מ"מ, בשטח מעל 3.0 מ"ר ועד 5.0 מ"ר | C26: מ"ר | D26: 0 | E26: 2060 | F26: =IF(E26="","",E26*0.15) -> 309 | G26: =IF(E26="","",E26*0.05) -> 103 | H26: =IF(E26="","",E26*1.05*0.85) -> 1838.55 | I26: =IF(D26="","",H26*D26) -> 0 | K26: כמות מנוע 30–50 | L26: 0
A27: 12.012.0130 | B27: חלון נגרר אגף על אגף של 3 אגפים ב-3 מסלולים מאולגן/צבוע כדוגמת קליל קלאסי 9000 או ש"ע, זכוכית שקופה בידודית מחוסמת דו צדדי 6+10+8 מ"מ, בשטח מעל 5.0 מ"ר ועד 7.0 מ"ר | C27: מ"ר | D27: 0 | E27: 1970 | F27: =IF(E27="","",E27*0.15) -> 295.5 | G27: =IF(E27="","",E27*0.05) -> 98.5 | H27: =IF(E27="","",E27*1.05*0.85) -> 1758.225 | I27: =IF(D27="","",H27*D27) -> 0 | K27: כמות מנוע 50–70 | L27: 3
A28: 12.012.0560 | B28: חלון נגרר אגף על אגף של 4 אגפים ב-2 מסלולים מאולגן/צבוע כדוגמת קליל קלאסי 9000 או ש"ע, זכוכית שקופה בידודית 6+10+8 מ"מ, בשטח מעל 3.0 מ"ר ועד 5.0 מ"ר | C28: מ"ר | D28: 0 | E28: 2300 | F28: =IF(E28="","",E28*0.15) -> 345 | G28: =IF(E28="","",E28*0.05) -> 115 | H28: =IF(E28="","",E28*1.05*0.85) -> 2052.75 | I28: =IF(D28="","",H28*D28) -> 0 | K28: כמות מנוע 70–90 | L28: 0
A29: 12.011.1001 | B29: תוספת עבור חלק קבוע בחלון נגרר אגף על אגף של 2 אגפים. התוספת הינה 15% למחיר מ"ר של החלון | C29: קומפ | D29: 19562.4 | E29: 0.15 | F29: =IF(E29="","",E29*0.15) -> 0.0225 | G29: =IF(E29="","",E29*0.05) -> 0.0075 | H29: =IF(E29="","",E29*1.05*0.85) -> 0.133875 | I29: =IF(D29="","",H29*D29) -> 2618.9163 | K29: כמות מנוע 90–120+ | L29: 1
A30: 12.011.9000 | B30: פירוק חלונות אלומיניום ומשקופיהם בשטח של עד 2 מ"ר | C30: יח' | D30: =L8 -> 0 | E30: 140 | F30: =IF(E30="","",E30*0.15) -> 21 | G30: =IF(E30="","",E30*0.05) -> 7 | H30: =IF(E30="","",E30*1.05*0.85) -> 124.95 | I30: =IF(D30="","",H30*D30) -> 0 | K30: כמות טיפול בארגז | L30: 0
A31: 12.011.9016 | B31: פירוק חלונות אלומיניום ומשקופיהם בשטח של מעל 2 מ"ר ועד 3 מ"ר | C31: יח' | D31: =L9 -> 0 | E31: 240 | F31: =IF(E31="","",E31*0.15) -> 36 | G31: =IF(E31="","",E31*0.05) -> 12 | H31: =IF(E31="","",E31*1.05*0.85) -> 214.2 | I31: =IF(D31="","",H31*D31) -> 0 | K31: סה"כ טקסאונד | L31: 2.292
A32: 12.011.9017 | B32: פירוק חלונות אלומיניום ומשקופיהם בשטח של מעל 3 מ"ר ועד 5 מ"ר | C32: יח' | D32: =L10 -> 3 | E32: 310 | F32: =IF(E32="","",E32*0.15) -> 46.5 | G32: =IF(E32="","",E32*0.05) -> 15.5 | H32: =IF(E32="","",E32*1.05*0.85) -> 276.675 | I32: =IF(D32="","",H32*D32) -> 830.025 | K32: שטח הזזה | L32: 0
A33: 12.014 | B33: חלון אלומיניום ציר צד וחלון דו-צירי סב-נטוי (DREH-KIPP) | K33: שטח הזזה+קבוע | L33: 11.115
A34: 12.014.0400 | B34: חלון ציר-צד מאולגן/צבוע כדוגמת קליל קלאסי 4500 או ש"ע, זכוכית שקופה בידודית 5+6+6 מ"מ, בשטח מעל 0.6 מ"ר ועד 1.0 מ"ר | C34: מ"ר | D34: 0 | E34: 2220 | F34: =IF(E34="","",E34*0.15) -> 333 | G34: =IF(E34="","",E34*0.05) -> 111 | H34: =IF(E34="","",E34*1.05*0.85) -> 1981.35 | I34: =IF(D34="","",H34*D34) -> 0 | K34: שטח קיפ | L34: 0
A35: 12.014.0650 | B35: חלון ציר-צד מאולגן/צבוע כדוגמת קליל קלאסי 4500 או ש"ע, זכוכית שקופה בידודית 5+6+6 מ"מ, בשטח מעל 0.6 מ"ר ועד 1.0 מ"ר | C35: מ"ר | D35: 0 | E35: 2790 | F35: =IF(E35="","",E35*0.15) -> 418.5 | G35: =IF(E35="","",E35*0.05) -> 139.5 | H35: =IF(E35="","",E35*1.05*0.85) -> 2490.075 | I35: =IF(D35="","",H35*D35) -> 0 | K35: שטח חלון ציר | L35: 0
A36: 12.014.0660 | B36: חלון דו-צירי סב נטוי (דריי קיפ), מאולגן/צבוע כדוגמת קליל קלאסי 4500 או ש"ע, זכוכית שקופה בידודית מחוסמת דו צדדי 6+10+8 מ"מ, בשטח מעל 1.0 מ"ר ועד 2.0 מ"ר | C36: מ"ר | D36: =L34+L6 -> 0 | E36: 2700 | F36: =IF(E36="","",E36*0.15) -> 405 | G36: =IF(E36="","",E36*0.05) -> 135 | H36: =IF(E36="","",E36*1.05*0.85) -> 2409.75 | I36: =IF(D36="","",H36*D36) -> 0 | K36: שטח תריסים לחלונות | L36: 11.115
A37: 12.016 | B37: חלון אלומיניום קיפ וחלון קבוע | K37: שטח תריסים לדלתות | L37: 7.85
A38: 12.016.0600 | B38: חלון קבוע כדוגמת קליל קלאסי 4500 או ש"ע, זכוכית שקופה בידודית 5+6+6 מ"מ, בשטח מעל 0.6 מ"ר ועד 1.0 מ"ר | C38: יח' | D38: 0 | E38: 1310 | F38: =IF(E38="","",E38*0.15) -> 196.5 | G38: =IF(E38="","",E38*0.05) -> 65.5 | H38: =IF(E38="","",E38*1.05*0.85) -> 1169.175 | I38: =IF(D38="","",H38*D38) -> 0 | K38: שטח דלת ציר | L38: 0
A39: 12.016.0610 | B39: חלון קבוע כדוגמת קליל קלאסי 4500 או ש"ע, זכוכית שקופה בידודית 5+6+6 מ"מ, בשטח מעל 1.0 מ"ר ועד 2.0 מ"ר | C39: יח' | D39: 0 | E39: 2090 | F39: =IF(E39="","",E39*0.15) -> 313.5 | G39: =IF(E39="","",E39*0.05) -> 104.5 | H39: =IF(E39="","",E39*1.05*0.85) -> 1865.325 | I39: =IF(D39="","",H39*D39) -> 0 | K39: מס' יחידות תריס לפירוק עד 2 מ"ר | L39: 0
A40: 12.051 | B40: דלתות/ויטרינות אלומיניום נגררות אגף על אגף (הזזה) של 2 אגפים | K40: סה"כ שטח תריס לפירוק מעל 2 מ"ר | L40: 18.965
...
