Workbook

Sheet 1549
C1: כהן אלדן | D1: 1549 | K1: נתוני מדידה גולמיים (קלט מריכוז כמויות)
K2: שדה | L2: ערך
K3: מס' חדרים | L3: 4
K4: היקף כולל | L4: 31.96
K5: שטח ויטרינה | L5: 7.85
A6: סעיף | B6: תאור | C6: יח' | D6: כמות | E6: מחיר | F6: הנחת קבלן 15% | G6: תוספת דירה מאוכלסת 5% | H6: סה"כ מחיר יחידה | I6: סה"כ אחרי הנחה | K6: שטח קיפ+קבוע | L6: 0
A7: 60.020.0090 | B7: חשמלאי מוסמך | C7: ש"ע | D7: =IF(SUM(D65,D66,D67,D68,D69,D70)>0,2,0) -> 2 | E7: 150 | F7: =IF(E7="","",E7*0.15) -> 22.5 | G7: =IF(E7="","",E7*0.05) -> 7.5 | H7: =IF(E7="","",E7*1.05*0.85) -> 133.875 | I7: =IF(D7="","",H7*D7) -> 267.75 | K7: שטח רשת כולל | L7: 10.817
A8: 09 | B8: עבודות טיח | K8: מס' חלונות עד 2 מ"ר | L8: 0
A9: 09.011 | B9: טיח פנים | K9: מס' חלונות מעל 2 מ"ר ועד 3 מ"ר | L9: 0
A10: 09.011.9030 | B10: תיקוני טיח פנים קיים על שטחים מישוריים ברצועות רוחב מעל 15 ס"מ ועד 30 ס"מ לאחר הנחת קווי מים, חשמל וכד' בקירות, סביב משקופי חלונות ודלתות שהורכבו בקירות קיימים, במפגשים בין קירות ו/או תקרות חדשים לקיימים הכל לרבות סיתות והתאמת עובי הטיח החדש לקיים | C10: מ' | D10: =L4 -> 31.96 | E10: 64 | F10: =IF(E10="","",E10*0.15) -> 9.6 | G10: =IF(E10="","",E10*0.05) -> 3.2 | H10: =IF(E10="","",E10*1.05*0.85) -> 57.12 | I10: =IF(D10="","",H10*D10) -> 1825.5552 | K10: מספר חלונות מעל 3 מ"ר ועד 5 מ"ר | L10: 3
A11: 11 | B11: עבודות צביעה | K11: רוחב 0-100 | L11: 0
A12: 11.011 | B12: צבע וסיוד פנים, על טיח, בטון, בלוקים וגבס | K12: רוחב 101-150 | L12: 3
A13: 11.011.9660 | B13: חידוש צבע פנים על קירות בדירת חדר מרוהטת בשטח 25-35 מ"ר ובגובה עד 2.70 מ'. הקירות ייצבעו בצבע אקרילי, ללא צביעת התקרות, לרבות הסרת צבע רופף, תיקונים קלים וסתימת חורים, ליטוש הקיר וניקוי שאריות הצבע בגמר העבודה | C13: קומפ | D13: =L3 -> 4 | E13: 1770 | F13: =IF(E13="","",E13*0.15) -> 265.5 | G13: =IF(E13="","",E13*0.05) -> 88.5 | H13: =IF(E13="","",E13*1.05*0.85) -> 1579.725 | I13: =IF(D13="","",H13*D13) -> 6318.9 | K13: רוחב 151-200 | L13: 0
K14: רוחב 201-250 | L14: 0
A15: 12 | B15: עבודות אלומיניום | K15: רוחב 251-300 | L15: 0
A16: 12.011 | B16: חלון אלומיניום נגרר אגף על אגף (הזזה) של 2 אגפים ב-2 מסלולים | K16: רוחב 301-350 | L16: 1
A17: 12.011.0210 | B17: חלון נגרר אגף על אגף של 2 אגפים ב-2 מסלולים מאולגן/צבוע כדוגמת קליל קלאסי 7000 או ש"ע, זכוכית שקופה בידודית 5+6+6 מ"מ, בשטח מעל 1.0 מ"ר ועד 2.0 מ"ר | C17: מ"ר | D17: 0 | E17: 1760 | F17: =IF(E17="","",E17*0.15) -> 264 | G17: =IF(E17="","",E17*0.05) -> 88 | H17: =IF(E17="","",E17*1.05*0.85) -> 1570.8 | I17: =IF(D17="","",H17*D17) -> 0 | K17: רוחב 351-400 | L17: 0
A18: 12.011.0260 | B18: חלון נגרר אגף על אגף של 2 אגפים ב-2 מסלולים מאולגן/צבוע כדוגמת קליל קלאסי 9000 או ש"ע, זכוכית שקופה בידודית 5+6+6 מ"מ, בשטח מעל 0.6 מ"ר ועד 1.0 מ"ר | C18: מ"ר | D18: 0 | E18: 2440 | F18: =IF(E18="","",E18*0.15) -> 366 | G18: =IF(E18="","",E18*0.05) -> 122 | H18: =IF(E18="","",E18*1.05*0.85) -> 2177.7 | I18: =IF(D18="","",H18*D18) -> 0 | K18: רוחב 401-450 | L18: 0
A19: 12.011.0265 | B19: חלון נגרר אגף על אגף של 2 אגפים ב-2 מסלולים מאולגן/צבוע כדוגמת קליל קלאסי 9000 או ש"ע, זכוכית שקופה בידודית 5+6+6 מ"מ, בשטח מעל 1.0 מ"ר ועד 2.0 מ"ר | C19: מ"ר | D19: 0 | E19: 2120 | F19: =IF(E19="","",E19*0.15) -> 318 | G19: =IF(E19="","",E19*0.05) -> 106 | H19: =IF(E19="","",E19*1.05*0.85) -> 1892.1 | I19: =IF(D19="","",H19*D19) -> 0 | K19: קומה 0-3 | L19: 0
A20: 12.011.0270 | B20: חלון נגרר אגף על אגף של 2 אגפים ב-2 מסלולים מאולגן/צבוע כדוגמת קליל קלאסי 9000 או ש"ע, זכוכית שקופה בידודית מחוסמת דו צדדי 6+10+8 מ"מ, בשטח מעל 2.0 מ"ר ועד 3.0 מ"ר | C20: מ"ר | D20: 0 | E20: 1980 | F20: =IF(E20="","",E20*0.15) -> 297 | G20: =IF(E20="","",E20*0.05) -> 99 | H20: =IF(E20="","",E20*1.05*0.85) -> 1767.15 | I20: =IF(D20="","",H20*D20) -> 0 | K20: קומה 4-7 | L20: 1
A21: 12.011.0275 | B21: חלון נגרר אגף על אגף של 2 אגפים ב-2 מסלולים מאולגן/צבוע כדוגמת קליל קלאסי 9000 או ש"ע, זכוכית שקופה בידודית מחוסמת דו צדדי 6+10+8 מ"מ, בשטח מעל 3.0 מ"ר ועד 4.0 מ"ר | C21: מ"ר | D21: 11.115 | E21: 1760 | F21: =IF(E21="","",E21*0.15) -> 264 | G21: =IF(E21="","",E21*0.05) -> 88 | H21: =IF(E21="","",E21*1.05*0.85) -> 1570.8 | I21: =IF(D21="","",H21*D21) -> 17459.442 | K21: קומה 7 ומעלה | L21: 0
A22: 12.011.0280 | B22: חלון נגרר אגף על אגף של 2 אגפים ב-2 מסלולים מאולגן/צבוע כדוגמת קליל קלאסי 9000 או ש"ע, זכוכית שקופה בידודית מחוסמת דו צדדי 6+10+10 מ"מ, בשטח מעל 4.0 מ"ר ועד 5.0 מ"ר | C22: מ"ר | D22: 0 | E22: 1630 | F22: =IF(E22="","",E22*0.15) -> 244.5 | G22: =IF(E22="","",E22*0.05) -> 81.5 | H22: =IF(E22="","",E22*1.05*0.85) -> 1454.775 | I22: =IF(D22="","",H22*D22) -> 0 | K22: שטח תריסים לחלונות (אור) | L22: 0
A23: 12.011.0285 | B23: חלון נגרר אגף על אגף של 2 אגפים ב-2 מסלולים מאולגן/צבוע כדוגמת קליל קלאסי 9000 או ש"ע, זכוכית שקופה בידודית מחוסמת דו צדדי 6+10+8 מ"מ, בשטח מעל 5.0 מ"ר ועד 6.0 מ"ר | C23: מ"ר | D23: 0 | E23: 1490 | F23: =IF(E23="","",E23*0.15) -> 223.5 | G23: =IF(E23="","",E23*0.05) -> 74.5 | H23: =IF(E23="","",E23*1.05*0.85) -> 1329.825 | I23: =IF(D23="","",H23*D23) -> 0 | K23: שטח תריסים לדלתות (אור) | L23: 0
A24: 12.012.0100 | B24: חלון נגרר אגף על אגף של 3 אגפים ב-3 מסלולים מאולגן/צבוע כדוגמת קליל קלאסי 9000 או ש"ע, זכוכית שקופה בידודית 5+6+6 מ"מ, בשטח מעל 1.0 מ"ר ועד 2.0 מ"ר | C24: מ"ר | D24: 0 | E24: 2210 | F24: =IF(E24="","",E24*0.15) -> 331.5 | G24: =IF(E24="","",E24*0.05) -> 110.5 | H24: =IF(E24="","",E24*1.05*0.85) -> 1972.425 | I24: =IF(D24="","",H24*D24) -> 0 | K24: כמות מנוע עד 20 | L24: 0
A25: 12.012.0110 | B25: חלון נגרר אגף על אגף של 3 אגפים ב-3 מסלולים מאולגן/צבוע כדוגמת קליל קלאסי 9000 או ש"ע, זכוכית שקופה בידודית 5+6+6 מ"מ, בשטח מעל 2.0 מ"ר ועד 3.0 מ"ר | C25: מ"ר | D25: 0 | E25: 2110 | F25: =IF(E25="","",E25*0.15) -> 316.5 | G25: =IF(E25="","",E25*0.05) -> 105.5 | H25: =IF(E25="","",E25*1.05*0.85) -> 1883.175 | I25: =IF(D25="","",H25*D25) -> 0 | K25: כמות מנוע 20–30 | L25: 0
A26: 12.012.0120 | B26: חלון נגרר אגף על אגף של 3 אגפים ב-3 מסלולים מאולגן/צבוע כדוגמת קליל קלאסי 9000 או ש"ע, זכוכית שקופה בידודית מחוסמת דו צדדי 6+10+8 מ"מ, בשטח מעל 3.0 מ"ר ועד 5.0 מ"ר | C26: מ"ר | D26: 0 | E26: 2060 | F26: =IF(E26="","",E26*0.15) -> 309 | G26: =IF(E26="","",E26*0.05) -> 103 | H26: =IF(E26="","",E26*1.05*0.85) -> 1838.55 | I26: =IF(D26="","",H26*D26) -> 0 | K26: כמות מנוע 30–50 | L26: 0
A27: 12.012.0130 | B27: חלון נגרר אגף על אגף של 3 אגפים ב-3 מסלולים מאולגן/צבוע כדוגמת קליל קלאסי 9000 או ש"ע, זכוכית שקופה בידודית מחוסמת דו צדדי 6+10+8 מ"מ, בשטח מעל 5.0 מ"ר ועד 7.0 מ"ר | C27: מ"ר | D27: 0 | E27: 1970 | F27: =IF(E27="","",E27*0.15) -> 295.5 | G27: =IF(E27="","",E27*0.05) -> 98.5 | H27: =IF(E27="","",E27*1.05*0.85) -> 1758.225 | I27: =IF(D27="","",H27*D27) -> 0 | K27: כמות מנוע 50–70 | L27: 3
A28: 12.012.0560 | B28: חלון נגרר אגף על אגף של 4 אגפים ב-2 מסלולים מאולגן/צבוע כדוגמת קליל קלאסי 9000 או ש"ע, זכוכית שקופה בידודית 6+10+8 מ"מ, בשטח מעל 3.0 מ"ר ועד 5.0 מ"ר | C28: מ"ר | D28: 0 | E28: 2300 | F28: =IF(E28="","",E28*0.15) -> 345 | G28: =IF(E28="","",E28*0.05) -> 115 | H28: =IF(E28="","",E28*1.05*0.85) -> 2052.75 | I28: =IF(D28="","",H28*D28) -> 0 | K28: כמות מנוע 70–90 | L28: 0
A29: 12.011.1001 | B29: תוספת עבור חלק קבוע בחלון נגרר אגף על אגף של 2 אגפים. התוספת הינה 15% למחיר מ"ר של החלון | C29: קומפ | D29: 19562.4 | E29: 0.15 | F29: =IF(E29="","",E29*0.15) -> 0.0225 | G29: =IF(E29="","",E29*0.05) -> 0.0075 | H29: =IF(E29="","",E29*1.05*0.85) -> 0.133875 | I29: =IF(D29="","",H29*D29) -> 2618.9163 | K29: כמות מנוע 90–120+ | L29: 1
A30: 12.011.9000 | B30: פירוק חלונות אלומיניום ומשקופיהם בשטח של עד 2 מ"ר | C30: יח' | D30: =L8 -> 0 | E30: 140 | F30: =IF(E30="","",E30*0.15) -> 21 | G30: =IF(E30="","",E30*0.05) -> 7 | H30: =IF(E30="","",E30*1.05*0.85) -> 124.95 | I30: =IF(D30="","",H30*D30) -> 0 | K30: כמות טיפול בארגז | L30: 0
A31: 12.011.9016 | B31: פירוק חלונות אלומיניום ומשקופיהם בשטח של מעל 2 מ"ר ועד 3 מ"ר | C31: יח' | D31: =L9 -> 0 | E31: 240 | F31: =IF(E31="","",E31*0.15) -> 36 | G31: =IF(E31="","",E31*0.05) -> 12 | H31: =IF(E31="","",E31*1.05*0.85) -> 214.2 | I31: =IF(D31="","",H31*D31) -> 0 | K31: סה"כ טקסאונד | L31: 2.292
A32: 12.011.9017 | B32: פירוק חלונות אלומיניום ומשקופיהם בשטח של מעל 3 מ"ר ועד 5 מ"ר | C32: יח' | D32: =L10 -> 3 | E32: 310 | F32: =IF(E32="","",E32*0.15) -> 46.5 | G32: =IF(E32="","",E32*0.05) -> 15.5 | H32: =IF(E32="","",E32*1.05*0.85) -> 276.675 | I32: =IF(D32="","",H32*D32) -> 830.025 | K32: שטח הזזה | L32: 0
A33: 12.014 | B33: חלון אלומיניום ציר צד וחלון דו-צירי סב-נטוי (DREH-KIPP) | K33: שטח הזזה+קבוע | L33: 11.115
A34: 12.014.0400 | B34: חלון ציר-צד מאולגן/צבוע כדוגמת קליל קלאסי 4500 או ש"ע, זכוכית שקופה בידודית 5+6+6 מ"מ, בשטח מעל 0.6 מ"ר ועד 1.0 מ"ר | C34: מ"ר | D34: 0 | E34: 2220 | F34: =IF(E34="","",E34*0.15) -> 333 | G34: =IF(E34="","",E34*0.05) -> 111 | H34: =IF(E34="","",E34*1.05*0.85) -> 1981.35 | I34: =IF(D34="","",H34*D34) -> 0 | K34: שטח קיפ | L34: 0
A35: 12.014.0650 | B35: חלון ציר-צד מאולגן/צבוע כדוגמת קליל קלאסי 4500 או ש"ע, זכוכית שקופה בידודית 5+6+6 מ"מ, בשטח מעל 0.6 מ"ר ועד 1.0 מ"ר | C35: מ"ר | D35: 0 | E35: 2790 | F35: =IF(E35="","",E35*0.15) -> 418.5 | G35: =IF(E35="","",E35*0.05) -> 139.5 | H35: =IF(E35="","",E35*1.05*0.85) -> 2490.075 | I35: =IF(D35="","",H35*D35) -> 0 | K35: שטח חלון ציר | L35: 0
A36: 12.014.0660 | B36: חלון דו-צירי סב נטוי (דריי קיפ), מאולגן/צבוע כדוגמת קליל קלאסי 4500 או ש"ע, זכוכית שקופה בידודית מחוסמת דו צדדי 6+10+8 מ"מ, בשטח מעל 1.0 מ"ר ועד 2.0 מ"ר | C36: מ"ר | D36: =L34+L6 -> 0 | E36: 2700 | F36: =IF(E36="","",E36*0.15) -> 405 | G36: =IF(E36="","",E36*0.05) -> 135 | H36: =IF(E36="","",E36*1.05*0.85) -> 2409.75 | I36: =IF(D36="","",H36*D36) -> 0 | K36: שטח תריסים לחלונות | L36: 11.115
A37: 12.016 | B37: חלון אלומיניום קיפ וחלון קבוע | K37: שטח תריסים לדלתות | L37: 7.85
A38: 12.016.0600 | B38: חלון קבוע כדוגמת קליל קלאסי 4500 או ש"ע, זכוכית שקופה בידודית 5+6+6 מ"מ, בשטח מעל 0.6 מ"ר ועד 1.0 מ"ר | C38: יח' | D38: 0 | E38: 1310 | F38: =IF(E38="","",E38*0.15) -> 196.5 | G38: =IF(E38="","",E38*0.05) -> 65.5 | H38: =IF(E38="","",E38*1.05*0.85) -> 1169.175 | I38: =IF(D38="","",H38*D38) -> 0 | K38: שטח דלת ציר | L38: 0
A39: 12.016.0610 | B39: חלון קבוע כדוגמת קליל קלאסי 4500 או ש"ע, זכוכית שקופה בידודית 5+6+6 מ"מ, בשטח מעל 1.0 מ"ר ועד 2.0 מ"ר | C39: יח' | D39: 0 | E39: 2090 | F39: =IF(E39="","",E39*0.15) -> 313.5 | G39: =IF(E39="","",E39*0.05) -> 104.5 | H39: =IF(E39="","",E39*1.05*0.85) -> 1865.325 | I39: =IF(D39="","",H39*D39) -> 0 | K39: מס' יחידות תריס לפירוק עד 2 מ"ר | L39: 0
A40: 12.051 | B40: דלתות/ויטרינות אלומיניום נגררות אגף על אגף (הזזה) של 2 אגפים | K40: סה"כ שטח תריס לפירוק מעל 2 מ"ר | L40: 18.965
...

Sheet פירוט כמויות
A2: פירוט כמויות
A3: הזמנה מס' | B3: ='1549'!D1 -> 1549 | D3: כתובת | E3: מנחם בגין 48, קומה 5 דירה 14
A7: תיאור המדידה | B7: כמות | C7: יח' מידה
A8: שטח חלונות הזזה | B8: =IFERROR(INDEX('1549'!D:D,MATCH(A11,'1549'!A:A,0)),"לא מוצא") -> 0 | C8: מ"ר
A9: מכיל את הסעיפים: | E9: אורך כפול רוחב החלון
A10: מס' סעיף | B10: תיאור סעיף
A11: 12.011.0270 | B11: חלון אגף על אגף
A12: 12.011.1001 | B12: תוספת עבור חלק קבוע
A13: 12.065.1613 | B13: תריס גלילה
A14: 12.093.0022 | B14: תוספת עבור צבע מטאלי
A16: תיאור המדידה | B16: כמות | C16: יח' מידה
A17: מטר אורך היקף חלונות וויטרינות | B17: =IFERROR(INDEX('1549'!D:D,MATCH(A20,'1549'!A:A,0)),"לא מוצא") -> 31.96 | C17: מטר
A18: מכיל את הסעיפים: | E18: פעמיים אורך החלון + פעמיים רוחב החלון אם מדובר בויטרינה - רוחב החלון נמדד רק פעם אחת
A19: מס' סעיף | B19: תיאור סעיף
A20: 09.011.9030 | B20: תיקוני טיח פנים על שטחים מישוריים
A23: תיאור המדידה | B23: כמות | C23: יח' מידה
A24: מס' חדרים | B24: =IFERROR(INDEX('1549'!D:D,MATCH(A27,'1549'!A:A,0)),"לא מוצא") -> 4 | C24: קומפ' | E24: מס' החדרים שבהם הוחלפו חלונות או ויטרינות סלון+מטבח נמדדים כחדר וחצי
A25: מכיל את הסעיפים:
A26: מס' סעיף | B26: תיאור סעיף
A27: 11.011.9660 | B27: חידוש צבע פנים לחדר כולל תיקונים
A30: תיאור המדידה | B30: כמות | C30: יח' מידה | E30: מס' החלונות שפורקו
A31: מס' חלונות | B31: =IFERROR(INDEX('1549'!D:D,MATCH(A34,'1549'!A:A,0)),"לא מוצא") -> 3 | C31: יח'
A32: מכיל את הסעיפים:
A33: מס' סעיף | B33: תיאור סעיף
A34: 12.011.9017 | B34: פירוק חלונות אלומיניום ומשקופיהם
A37: תיאור המדידה | B37: כמות | C37: יח' מידה | E37: אורך כפול רוחב הויטרינה
A38: שטח ויטרינות | B38: =IFERROR(INDEX('1549'!D:D,MATCH(A41,'1549'!A:A,0)),"לא מוצא") -> 7.85 | C38: מ"ר
A39: מכיל את הסעיפים:
A40: מס' סעיף | B40: תיאור סעיף
A41: 12.052.0070 | B41: דלת נגררת אגף על אגף של 3 אגפים ב-3 מסלולים מאולגנת/צבועה כדוגמת קליל קלאסי 9000 או ש"ע, זכוכית מחוסמת בעובי 6 מ"מ, בשטח מעל 6.0 מ"ר ועד 8.0 מ"ר
A42: 12.061.9000 | B42: פירוק ויטרינה מאלומיניום, לרבות המשקוף
A43: 12.068.1216 | B43: זכוכית שקופה בידודית מחוסמת משני הצדדים 6+10+8 מ"מ
A44: 12.068.1004 | B44: הפחתת זכוכית שטוחה מחוסמת בעובי 6 מ"מ
A45: 12.065.1615 | B45: תריס גלילה עם רפפות מפח אלומיניום עם פוליאוריטן מוקצף לרבות ארגז תריס מונובלוק 40, בשטח מעל 3.0 מ"ר ועד 6.0 מ"ר
A46: 12.093.0022 | B46: תוספת עבור צבע מטאלי
A48: תיאור המדידה | B48: כמות | C48: יח' מידה | E48: כמות המנועים שהוחלפו פירוט הכמות נמצא בכתב הכמויות כדי לא להעמיס על המסמך
A49: מנועים חשמליים | B49: =SUM(D52:D57) -> 4 | C49: יח'
A50: מכיל את הסעיפים:
A51: מס' סעיף | B51: תיאור סעיף | D51: כמות
A52: 12.065.2000 | B52: מנוע חשמלי לתריס במשקל עד 20 ק"ג, לא כולל נק' החשמל | D52: =IFERROR(INDEX('1549'!D:D,MATCH(A52,'1549'!A:A,0)),0) -> 0
...
